Workbook
Name Ligduur_Bron: Instellingen!$C$6
Name Start_Idx: Instellingen!$C$7
Name Eind_Idx: Instellingen!$C$8
Name Ondergrens_U: Instellingen!$C$11
Name Bovengrens_U: Instellingen!$C$12
Name Dedup_Regel: Instellingen!$C$15
Name Dedup_Nr: Instellingen!$C$16
Name Best_Kolom: Instellingen!$C$19
Name Best_Idx: Instellingen!$C$20
Name Best_Waarde: Instellingen!$C$21
Name Filter_Aan: Instellingen!$C$25
Name Filter_Kolom: Instellingen!$C$26
Name Filter_Idx: Instellingen!$C$27
Name Filter_Zoek: Instellingen!$C$28
Name Filter_Waarde: Instellingen!$C$29
Name Scenario_Gebruiken: Instellingen!$C$33
Name Tijd_Bekend_Ja: Instellingen!$C$34
Name Excl_Onbetrouwbaar: Instellingen!$C$35

Sheet Handleiding
B2: EHH ligduur analyse
B3: Ligduur, ontslagbestemming en potentiele tijdwinst.
B5: STAP 1 - Data plakken
C6: Ga naar tabblad 'Data'. Rij 1 bevat exact uw 28 kolomnamen in dezelfde volgorde.
C7: Klik op cel A2 en plak uw dataset zonder de kopregel, via Plakken > Waarden.
C8: Plak NIET over kolom AD en verder heen: daar horen de formules.
B10: STAP 2 - Formules doortrekken (BELANGRIJK)
C11: De formules staan alleen in rij 2, zodat het bestand klein blijft en
C12: Excel het zonder foutmelding opent. Trek ze zelf door:
C13: 1. selecteer AD2 tot en met AS2
C14: 2. Ctrl+C
C15: 3. selecteer AD3 tot en met AS<uw laatste rij>
C16: (tip: Ctrl+Shift+Pijl-omlaag selecteert tot onderaan)
C17: 4. Ctrl+V
C18: Blok 0 op het Dashboard controleert of u ver genoeg bent gekomen en
C19: meldt het als de formules nog niet bij uw laatste datarij zijn.
C20: Let op: dubbelklikken op het vulblokje werkt hier vaak niet, doordat er
C21: een lege kolom (AC) tussen uw data en de formules staat. Gebruik kopieren
C22: en plakken zoals hierboven; dat werkt altijd.
B24: STAP 3 - Instellingen controleren
C25: Op 'Instellingen' zijn alle gele cellen aanpasbaar. Standaard staat de
C26: tijdbron op 'Opname totaal' en telt elke opname een keer, ook als die
C27: door een kamerwissel over meerdere regels loopt.
B29: STAP 4 - Antwoorden lezen
C30: 'Dashboard' = alle kerncijfers, met bovenaan een controleblok.
C31: 'Verdeling' = alle opnames per ligduurblok van 2 uur.
C32: 'Data' = per regel, inclusief de reden waarom hij meetelt of niet.
B34: GESORTEERDE LIJST OP KORTSTE LIGDUUR
C35: Op 'Data' staat een filter klaar in rij 1. Filter kolom AD op de waarde 1,
C36: klik dan op het filterpijltje van 'Ligduur (uren)' en kies Sorteren van
C37: klein naar groot. U ziet dan de selectie met de kortste ligduur bovenaan.
C38: Let op: sorteer pas nadat u de formules heeft doorgetrokken.
B40: WAAROM TELT EEN REGEL NIET MEE?
C41: Kolom 'Status / reden' op 'Data' geeft per regel het antwoord:
B42: Extra regel van dezelfde opname | C42: Tweede of latere regel van dezelfde opname (bijvoorbeeld kamerwissel).
B43: Geen geldige start- of eindtijd | C43: Start- of eindtijd ontbreekt of is geen geldige datum.
B44: Te kort (t/m ondergrens) | C44: Ligduur is niet langer dan de ondergrens.
B45: Te lang (boven bovengrens) | C45: Ligduur is langer dan de bovengrens.
B46: Buiten het extra filter | C46: Valt buiten het optionele extra filter.
B47: Tijd onbetrouwbaar (uitgesloten) | C47: 'Tijd bekend' is niet bevestigend en u heeft uitsluiten aangezet.
...

Sheet Instellingen
B2: Instellingen
B3: Alle gele cellen kunt u aanpassen. De analyse rekent direct mee.
B5: A. Welke tijden bepalen de ligduur? | E5: Tijdbron | F5: Gebruikt kolommen
B6: Tijdbron | C6: Opname totaal (aanbevolen) | E6: Opname totaal (aanbevolen) | F6: OpnameDatumTijdVan -> OpnameDatumTijdTotEnMet: de hele opname | G6: 4 | H6: 5
B7: kolomnummer start (automatisch) | C7: =IFERROR(INDEX($G$6:$G$8,MATCH($C$6,$E$6:$E$8,0)),4) | E7: Opnameperiode (deelperiode) | F7: OpnameperiodeDatumTijdVan -> ...TotEnMet: per kamer/deelperiode | G7: 7 | H7: 8
B8: kolomnummer eind (automatisch) | C8: =IFERROR(INDEX($H$6:$H$8,MATCH($C$6,$E$6:$E$8,0)),5) | E8: Datum tijd van / tot en met | F8: Uw eigen kolommen 'Datum tijd van' en 'Datum tot en met' | G8: 21 | H8: 22
B10: B. Selectiegrenzen | E10: Een regel per opname | F10: Toelichting
B11: Ondergrens ligduur in uren (exclusief) | C11: 6 | E11: Ja - periodestart = opnamestart | F11: Telt de regel waarvan de deelperiode op hetzelfde moment begint als de opname. Werkt ongeacht de sorteervolgorde. Aanbevolen.
B12: Bovengrens ligduur in uren (inclusief) | C12: 24 | E12: Ja - eerste regel per OpnameIDIntern | F12: Vergelijkt met de regel erboven. Vereist dat de data op OpnameIDIntern gesorteerd staat.
E13: Nee - elke regel telt mee | F13: Gebruik dit als u deelperiodes wilt tellen in plaats van opnames.
B14: C. Dubbele regels van dezelfde opname
B15: Een regel per opname? | C15: Ja - periodestart = opnamestart | E15: Ja / Nee
B16: volgnummer regel (automatisch) | C16: =IFERROR(MATCH($C$15,$E$11:$E$13,0),1) | E16: Ja
E17: Nee
B18: D. Naar huis of in het ziekenhuis gebleven?
B19: Kolom die aangeeft dat de patient NIET naar huis ging | C19: Overname? | E19: Zoekwijze
B20: kolomnummer (automatisch) | C20: =IFERROR(MATCH($C$19,$E$24:$E$51,0),19) | E20: Bevat
B21: Waarde die 'niet naar huis' betekent | C21: Ja | E21: Is exact gelijk aan
B22: aantal regels dat hierop matcht | C22: =COUNTIF(Data!$AJ$2:$AJ$250001,"Blijft in ziekenhuis")
E23: Kolommen in de export
B24: E. Extra filter (optioneel) | E24: OpnameIDIntern
B25: Extra filter gebruiken? | C25: Nee | E25: CodePreferent
B26: Filterkolom | C26: SpecialismeCodeIntern | E26: Jaar
B27: kolomnummer (automatisch) | C27: =IFERROR(MATCH($C$26,$E$24:$E$51,0),13) | E27: OpnameDatumTijdVan
B28: Zoekwijze | C28: Bevat | E28: OpnameDatumTijdTotEnMet
B29: Filterwaarde | C29: CAR | E29: OpnameperiodeIDIntern
B30: aantal regels dat hierop matcht | C30: =IF(Filter_Aan="Nee","filter staat uit",COUNTIF(Data!$AE$2:$AE$250001,"Buiten het extra filter")) | E30: OpnameperiodeDatumTijdVan
E31: OpnameperiodeDatumTijdTotEnMet
B32: F. Scenario's en datakwaliteit | E32: AfdelingCode
B33: Scenariokolommen uit de data gebruiken? | C33: Ja | E33: KamerCode
B34: Waarde in 'Tijd bekend' die 'ja' betekent | C34: Ja | E34: Code
B35: Regels met onbetrouwbare tijd uitsluiten? | C35: Nee | E35: IsSpoedOpname
E36: SpecialismeCodeIntern
E37: OpnameDiagnoseOmschrijving
E38: OmschrijvingIntern
E39: OP_AantalOpnamePeriode
E40: OP_DoorlooptijdOpnamePeriodeInMinuten
E41: Cardioversie?
E42: Overname?
E43: Rijnstate
...

Sheet Data
A1: OpnameIDIntern | B1: CodePreferent | C1: Jaar | D1: OpnameDatumTijdVan | E1: OpnameDatumTijdTotEnMet | F1: OpnameperiodeIDIntern | G1: OpnameperiodeDatumTijdVan | H1: OpnameperiodeDatumTijdTotEnMet | I1: AfdelingCode | J1: KamerCode | K1: Code | L1: IsSpoedOpname | M1: SpecialismeCodeIntern | N1: OpnameDiagnoseOmschrijving | O1: OmschrijvingIntern | P1: OP_AantalOpnamePeriode | Q1: OP_DoorlooptijdOpnamePeriodeInMinuten | R1: Cardioversie? | S1: Overname? | T1: Rijnstate | U1: Datum tijd van | V1: Datum tot en met | W1: Ontslagdatumtijd Scenario 1 - 4 uur | X1: Ontslagdatumtijd Scenario 2 - 6 uur | Y1: Ontslagdatumtijd Scenario 3 - 24 uur | Z1: Patientvolgorde | AA1: CCU-Eerst? | AB1: Tijd bekend | AD1: In selectie (1/0) | AE1: Status / reden | AF1: Ligduur (uren) | AG1: Ligduur (d/u/m) | AH1: Start | AI1: Eind | AJ1: Bestemming | AK1: Winst t.o.v. 4 uur | AL1: Winst t.o.v. 6 uur | AM1: Winst t.o.v. 24 uur | AN1: Eerste regel van opname | AO1: Ligduur in selectie | AP1: Winst in selectie | AQ1: Controle vs doorlooptijd | AR1: hulp: start ruw | AS1: hulp: eind ruw
AD2: =IF(OR($AE2="In selectie - naar huis",$AE2="In selectie - blijft in ziekenhuis"),1,0) | AE2: =IF(TRIM($A2&"")="","",IF($AN2=0,"Extra regel van dezelfde opname",IF($AF2="","Geen geldige start- of eindtijd",IF(NOT(IF(Filter_Aan="Nee",TRUE,IF(Filter_Zoek="Bevat",ISNUMBER(SEARCH(Filter_Waarde,INDEX($A2:$AB2,Filter_Idx)&"")),UPPER(TRIM(INDEX($A2:$AB2,Filter_Idx)&""))=UPPER(TRIM(Filter_Waarde&""))))),"Buiten het extra filter",IF(AND(Excl_Onbetrouwbaar="Ja",TRIM($AB2&"")<>"",NOT(OR(UPPER(TRIM($AB2&""))=UPPER(TRIM(Tijd_Bekend_Ja&"")),TRIM($AB2&"")="1",UPPER(TRIM($AB2&""))="WAAR",UPPER(TRIM($AB2&""))="TRUE",UPPER(TRIM($AB2&""))="J",UPPER(TRIM($AB2&""))="Y"))),"Tijd onbetrouwbaar (uitgesloten)",IF($AF2<=Ondergrens_U,"Te kort (t/m ondergrens)",IF($AF2>Bovengrens_U,"Te lang (boven bovengrens)",IF($AJ2="Naar huis","In selectie - naar huis","In selectie - blijft in ziekenhuis")))))))) | AF2: =IF(OR(NOT(ISNUMBER($AH2)),NOT(ISNUMBER($AI2)),$AI2<$AH2),"",ROUND(($AI2-$AH2)*24,4)) | AG2: =IF($AF2="","",INT($AF2/24)&"d "&TEXT(INT(MOD($AF2,24)),"00")&"u "&TEXT(ROUND(MOD($AF2*60,60),0),"00")&"m") | AH2: =IF(OR(TRIM($AR2&"")="",$AR2=0),"",IFERROR(IF(ISNUMBER($AR2),$AR2,--SUBSTITUTE(TRIM($AR2&""),"T"," ")),"")) | AI2: =IF(OR(TRIM($AS2&"")="",$AS2=0),"",IFERROR(IF(ISNUMBER($AS2),$AS2,--SUBSTITUTE(TRIM($AS2&""),"T"," ")),"")) | AJ2: =IF(TRIM(INDEX($A2:$AB2,Best_Idx)&"")="","Naar huis",IF(OR(UPPER(TRIM(INDEX($A2:$AB2,Best_Idx)&""))=UPPER(TRIM(Best_Waarde&"")),TRIM(INDEX($A2:$AB2,Best_Idx)&"")="1",UPPER(TRIM(INDEX($A2:$AB2,Best_Idx)&""))="WAAR",UPPER(TRIM(INDEX($A2:$AB2,Best_Idx)&""))="TRUE",UPPER(TRIM(INDEX($A2:$AB2,Best_Idx)&""))="J",UPPER(TRIM(INDEX($A2:$AB2,Best_Idx)&""))="Y"),"Blijft in ziekenhuis","Naar huis")) | AK2: =IF(OR($AF2="",$AJ2<>"Naar huis"),"",MAX(0,ROUND(($AI2-IF(AND(Scenario_Gebruiken="Ja",ISNUMBER($W2),$W2>0),$W2,MIN($AI2,$AH2+4/24)))*24,2))) | AL2: =IF(OR($AF2="",$AJ2<>"Naar huis"),"",MAX(0,ROUND(($AI2-IF(AND(Scenario_Gebruiken="Ja",ISNUMBER($X2),$X2>0),$X2,MIN($AI2,$AH2+6/24)))*24,2))) | AM2: =IF(OR($AF2="",$AJ2<>"Naar huis"),"",MAX(0,ROUND(($AI2-IF(AND(Scenario_Gebruiken="Ja",ISNUMBER($Y2),$Y2>0),$Y2,MIN($AI2,$AH2+24/24)))*24,2))) | AN2: =IF(Dedup_Nr=3,1,IF(Dedup_Nr=2,IF(TRIM($A2&"")="",0,IF($A2<>$A1,1,0)),IF(OR(TRIM($D2&"")="",TRIM($G2&"")=""),1,IF(ROUND(IFERROR(IF(ISNUMBER($G2),$G2,--SUBSTITUTE(TRIM($G2&""),"T"," ")),"")-IFERROR(IF(ISNUMBER($D2),$D2,--SUBSTITUTE(TRIM($D2&""),"T"," ")),""),6)=0,1,0)))) | AO2: =IF($AD2=1,$AF2,"") | AP2: =IF(AND($AD2=1,ISNUMBER($AL2)),$AL2,"") | AQ2: =IF(OR($AF2="",NOT(ISNUMBER($Q2))),"",ROUND($AF2*60,0)-$Q2) | AR2: =INDEX($A2:$AB2,Start_Idx) | AS2: =INDEX($A2:$AB2,Eind_Idx)

Sheet Dashboard
B2: Dashboard EHH ligduur
B3: Lees eerst blok 0. Alle cijfers volgen de instellingen.
B5: 0. Eerst controleren | C5: Aantal | G5: Toelichting
B6: Regels ingelezen | C6: =COUNTIF(Data!$A$2:$A$250001,"?*")+COUNT(Data!$A$2:$A$250001) | G6: Nul betekent dat er nog geen data geplakt is.
B7: Regels waar de formules staan | C7: =COUNTIF(Data!$AE$2:$AE$250001,"?*") | G7: Is dit lager dan 'Regels ingelezen', dan zijn de formules nog niet ver genoeg doorgetrokken. Zie de Handleiding, stap 2.
B8: Unieke opnames (na ontdubbelen) | C8: =SUMIF(Data!$AN$2:$AN$250001,1) | G8: Een opname met kamerwissel staat op meerdere regels; hier telt elke opname een keer.
B9: Regels met een geldige ligduur | C9: =COUNT(Data!$AF$2:$AF$250001) | G9: Blijft dit achter, dan staat de verkeerde tijdbron ingesteld.
B10: =IF(COUNTIF(Data!$A$2:$A$250001,"?*")+COUNT(Data!$A$2:$A$250001)=0,"Nog geen data geplakt op het tabblad Data.",IF(COUNTIF(Data!$AE$2:$AE$250001,"?*")<COUNTIF(Data!$A$2:$A$250001,"?*")+COUNT(Data!$A$2:$A$250001),"LET OP: de formules staan pas op "&COUNTIF(Data!$AE$2:$AE$250001,"?*")&" van de "&COUNTIF(Data!$A$2:$A$250001,"?*")+COUNT(Data!$A$2:$A$250001)&" regels. Trek AD2:AS2 door naar beneden; tot die tijd zijn de cijfers hieronder onvolledig.",IF(COUNT(Data!$AF$2:$AF$250001)=0,"LET OP: geen enkele regel heeft een geldige ligduur. Controleer de tijdbron op het tabblad Instellingen.","Controle in orde - de cijfers hieronder kloppen.")))
B12: 1. Selectie: langer dan de ondergrens tot en met de bovengrens | C12: Aantal | D12: % van selectie | E12: Uren | F12: Bedddagen | G12: Toelichting
B13: SELECTIE: langer dan ondergrens t/m bovengrens | C13: =COUNTIFS(Data!$AD$2:$AD$250001,1) | E13: =IF(COUNT(Data!$AO$2:$AO$250001)=0,"",ROUND(SUM(Data!$AO$2:$AO$250001),1)) | F13: =IF(COUNT(Data!$AO$2:$AO$250001)=0,"",ROUND(SUM(Data!$AO$2:$AO$250001)/24,1)) | G13: DIT IS DE GEVRAAGDE FILTERGROEP. Een opname telt hier een keer, ook bij een kamerwissel.
B14: waarvan met ontslag naar huis gegaan | C14: =COUNTIFS(Data!$AD$2:$AD$250001,1,Data!$AJ$2:$AJ$250001,"Naar huis") | D14: =IF(COUNTIFS(Data!$AD$2:$AD$250001,1)=0,"",COUNTIFS(Data!$AD$2:$AD$250001,1,Data!$AJ$2:$AJ$250001,"Naar huis")/COUNTIFS(Data!$AD$2:$AD$250001,1)) | G14: Het aantal opnames dat u hiermee kunt faciliteren.
B15: waarvan in het ziekenhuis gebleven | C15: =COUNTIFS(Data!$AD$2:$AD$250001,1,Data!$AJ$2:$AJ$250001,"Blijft in ziekenhuis") | D15: =IF(COUNTIFS(Data!$AD$2:$AD$250001,1)=0,"",COUNTIFS(Data!$AD$2:$AD$250001,1,Data!$AJ$2:$AJ$250001,"Blijft in ziekenhuis")/COUNTIFS(Data!$AD$2:$AD$250001,1)) | G15: IMPACT KLINIEK: deze patienten hebben na de ondergrens een klinisch bed nodig.
B16: die eerder naar huis hadden gekund | C16: =COUNTIFS(Data!$AD$2:$AD$250001,1,Data!$AJ$2:$AJ$250001,"Naar huis",Data!$AL$2:$AL$250001,">0") | D16: =IF(COUNTIFS(Data!$AD$2:$AD$250001,1)=0,"",COUNTIFS(Data!$AD$2:$AD$250001,1,Data!$AJ$2:$AJ$250001,"Naar huis",Data!$AL$2:$AL$250001,">0")/COUNTIFS(Data!$AD$2:$AD$250001,1)) | G16: Staat de ondergrens op 6 uur, dan is dit per definitie gelijk aan de regel hierboven. Blok 3 toont het effect van afkappen op 4 uur.
B17: totale tijdwinst van die groep | E17: =IF(COUNT(Data!$AP$2:$AP$250001)=0,"",ROUND(SUM(Data!$AP$2:$AP$250001),1)) | F17: =IF(COUNT(Data!$AP$2:$AP$250001)=0,"",ROUND(SUM(Data!$AP$2:$AP$250001)/24,1)) | G17: Vrijgespeelde EHH-tijd bij ontslag op de ondergrens.
B18: gemiddelde tijdwinst per patient | E18: =IF(COUNT(Data!$AP$2:$AP$250001)=0,"",ROUND(AVERAGE(Data!$AP$2:$AP$250001),2)) | G18: Gemiddeld aantal uren dat een patient te lang lag.
B19: mediane tijdwinst per patient | E19: =IF(COUNT(Data!$AP$2:$AP$250001)=0,"",ROUND(MEDIAN(Data!$AP$2:$AP$250001),2)) | G19: Minder gevoelig voor uitschieters.
B21: 2. Ligduur binnen de selectie | C21: Uren
B22: Kortste ligduur | C22: =IF(COUNT(Data!$AO$2:$AO$250001)=0,"",ROUND(MIN(Data!$AO$2:$AO$250001),2))
B23: Mediane ligduur | C23: =IF(COUNT(Data!$AO$2:$AO$250001)=0,"",ROUND(MEDIAN(Data!$AO$2:$AO$250001),2))
B24: Gemiddelde ligduur | C24: =IF(COUNT(Data!$AO$2:$AO$250001)=0,"",ROUND(AVERAGE(Data!$AO$2:$AO$250001),2))
B25: Langste ligduur | C25: =IF(COUNT(Data!$AO$2:$AO$250001)=0,"",ROUND(MAX(Data!$AO$2:$AO$250001),2))
B26: 90e percentiel ligduur | C26: =IF(COUNT(Data!$AO$2:$AO$250001)=0,"",ROUND(PERCENTILE(Data!$AO$2:$AO$250001,0.9),2))
B28: 3. Scenario's - afkappen op 4, 6 en 24 uur (alleen naar huis) | C28: Alle opnames | D28: In selectie | E28: Winst uren | F28: Bedddagen
B29: Scenario 1 - afkappen op 4 uur | C29: =COUNTIFS(Data!$AN$2:$AN$250001,1,Data!$AJ$2:$AJ$250001,"Naar huis",Data!$AK$2:$AK$250001,">0") | D29: =COUNTIFS(Data!$AD$2:$AD$250001,1,Data!$AJ$2:$AJ$250001,"Naar huis",Data!$AK$2:$AK$250001,">0") | E29: =IF(COUNT(Data!$AK$2:$AK$250001)=0,"",ROUND(SUMIFS(Data!$AK$2:$AK$250001,Data!$AN$2:$AN$250001,1,Data!$AJ$2:$AJ$250001,"Naar huis"),1)) | F29: =IF(COUNT(Data!$AK$2:$AK$250001)=0,"",ROUND(SUMIFS(Data!$AK$2:$AK$250001,Data!$AN$2:$AN$250001,1,Data!$AJ$2:$AJ$250001,"Naar huis")/24,1)) | G29: Opnames die langer dan 4 uur duurden en toch naar huis gingen, met de tijd die zij te lang lagen.
B30: Scenario 2 - afkappen op 6 uur | C30: =COUNTIFS(Data!$AN$2:$AN$250001,1,Data!$AJ$2:$AJ$250001,"Naar huis",Data!$AL$2:$AL$250001,">0") | D30: =COUNTIFS(Data!$AD$2:$AD$250001,1,Data!$AJ$2:$AJ$250001,"Naar huis",Data!$AL$2:$AL$250001,">0") | E30: =IF(COUNT(Data!$AL$2:$AL$250001)=0,"",ROUND(SUMIFS(Data!$AL$2:$AL$250001,Data!$AN$2:$AN$250001,1,Data!$AJ$2:$AJ$250001,"Naar huis"),1)) | F30: =IF(COUNT(Data!$AL$2:$AL$250001)=0,"",ROUND(SUMIFS(Data!$AL$2:$AL$250001,Data!$AN$2:$AN$250001,1,Data!$AJ$2:$AJ$250001,"Naar huis")/24,1)) | G30: Opnames die langer dan 6 uur duurden en toch naar huis gingen, met de tijd die zij te lang lagen.
B31: Scenario 3 - afkappen op 24 uur | C31: =COUNTIFS(Data!$AN$2:$AN$250001,1,Data!$AJ$2:$AJ$250001,"Naar huis",Data!$AM$2:$AM$250001,">0") | D31: =COUNTIFS(Data!$AD$2:$AD$250001,1,Data!$AJ$2:$AJ$250001,"Naar huis",Data!$AM$2:$AM$250001,">0") | E31: =IF(COUNT(Data!$AM$2:$AM$250001)=0,"",ROUND(SUMIFS(Data!$AM$2:$AM$250001,Data!$AN$2:$AN$250001,1,Data!$AJ$2:$AJ$250001,"Naar huis"),1)) | F31: =IF(COUNT(Data!$AM$2:$AM$250001)=0,"",ROUND(SUMIFS(Data!$AM$2:$AM$250001,Data!$AN$2:$AN$250001,1,Data!$AJ$2:$AJ$250001,"Naar huis")/24,1)) | G31: Opnames die langer dan 24 uur duurden en toch naar huis gingen, met de tijd die zij te lang lagen.
B33: 4. Alle regels naar status | C33: Aantal | D33: % van regels
B34: In selectie - naar huis | C34: =COUNTIFS(Data!$AE$2:$AE$250001,"In selectie - naar huis") | D34: =IF(COUNTIF(Data!$AE$2:$AE$250001,"?*")=0,"",COUNTIFS(Data!$AE$2:$AE$250001,"In selectie - naar huis")/COUNTIF(Data!$AE$2:$AE$250001,"?*"))
B35: In selectie - blijft in ziekenhuis | C35: =COUNTIFS(Data!$AE$2:$AE$250001,"In selectie - blijft in ziekenhuis") | D35: =IF(COUNTIF(Data!$AE$2:$AE$250001,"?*")=0,"",COUNTIFS(Data!$AE$2:$AE$250001,"In selectie - blijft in ziekenhuis")/COUNTIF(Data!$AE$2:$AE$250001,"?*"))
B36: Te kort (t/m ondergrens) | C36: =COUNTIFS(Data!$AE$2:$AE$250001,"Te kort (t/m ondergrens)") | D36: =IF(COUNTIF(Data!$AE$2:$AE$250001,"?*")=0,"",COUNTIFS(Data!$AE$2:$AE$250001,"Te kort (t/m ondergrens)")/COUNTIF(Data!$AE$2:$AE$250001,"?*"))
B37: Te lang (boven bovengrens) | C37: =COUNTIFS(Data!$AE$2:$AE$250001,"Te lang (boven bovengrens)") | D37: =IF(COUNTIF(Data!$AE$2:$AE$250001,"?*")=0,"",COUNTIFS(Data!$AE$2:$AE$250001,"Te lang (boven bovengrens)")/COUNTIF(Data!$AE$2:$AE$250001,"?*"))
B38: Geen geldige start- of eindtijd | C38: =COUNTIFS(Data!$AE$2:$AE$250001,"Geen geldige start- of eindtijd") | D38: =IF(COUNTIF(Data!$AE$2:$AE$250001,"?*")=0,"",COUNTIFS(Data!$AE$2:$AE$250001,"Geen geldige start- of eindtijd")/COUNTIF(Data!$AE$2:$AE$250001,"?*"))
B39: Extra regel van dezelfde opname | C39: =COUNTIFS(Data!$AE$2:$AE$250001,"Extra regel van dezelfde opname") | D39: =IF(COUNTIF(Data!$AE$2:$AE$250001,"?*")=0,"",COUNTIFS(Data!$AE$2:$AE$250001,"Extra regel van dezelfde opname")/COUNTIF(Data!$AE$2:$AE$250001,"?*"))
B40: Buiten het extra filter | C40: =COUNTIFS(Data!$AE$2:$AE$250001,"Buiten het extra filter") | D40: =IF(COUNTIF(Data!$AE$2:$AE$250001,"?*")=0,"",COUNTIFS(Data!$AE$2:$AE$250001,"Buiten het extra filter")/COUNTIF(Data!$AE$2:$AE$250001,"?*"))
B41: Tijd onbetrouwbaar (uitgesloten) | C41: =COUNTIFS(Data!$AE$2:$AE$250001,"Tijd onbetrouwbaar (uitgesloten)") | D41: =IF(COUNTIF(Data!$AE$2:$AE$250001,"?*")=0,"",COUNTIFS(Data!$AE$2:$AE$250001,"Tijd onbetrouwbaar (uitgesloten)")/COUNTIF(Data!$AE$2:$AE$250001,"?*"))
B42: Totaal met formule | C42: =SUM(C34:C41) | G42: Moet gelijk zijn aan 'Regels waar de formules staan'.
B44: 5. Datakwaliteit | C44: Aantal
B45: Regels zonder geldige start- of eindtijd | C45: =COUNTIFS(Data!$AE$2:$AE$250001,"Geen geldige start- of eindtijd") | G45: Controleer de tijdbron en of de datums als datum geplakt zijn.
B46: Regels waar de ligduur afwijkt van OP_Doorlooptijd... | C46: =COUNTIFS(Data!$AQ$2:$AQ$250001,"<>0",Data!$AQ$2:$AQ$250001,"<>") | G46: Bij tijdbron 'Opname totaal' is afwijking normaal: die kolom gaat over de deelperiode, niet over de hele opname.
B47: Grootste afwijking in minuten | C47: =IF(COUNT(Data!$AQ$2:$AQ$250001)=0,"",MAX(MAX(Data!$AQ$2:$AQ$250001),-MIN(Data!$AQ$2:$AQ$250001))) | G47: Nul betekent exacte overeenstemming met de brondata.

Sheet Verdeling
B2: Verdeling van de ligduur
B3: Alle unieke opnames, per blok van 2 uur.
B5: Ligduurblok | C5: Vanaf | D5: Tot | E5: Aantal | F5: Naar huis | G5: Blijft in ziekenhuis | H5: Winst uren (6u) | I5: % van totaal
B6: 0 tot 2 uur | C6: 0 | D6: 2 | E6: =COUNTIFS(Data!$AN$2:$AN$250001,1,Data!$AF$2:$AF$250001,">"&$C6,Data!$AF$2:$AF$250001,"<="&$D6) | F6: =COUNTIFS(Data!$AN$2:$AN$250001,1,Data!$AF$2:$AF$250001,">"&$C6,Data!$AF$2:$AF$250001,"<="&$D6,Data!$AJ$2:$AJ$250001,"Naar huis") | G6: =COUNTIFS(Data!$AN$2:$AN$250001,1,Data!$AF$2:$AF$250001,">"&$C6,Data!$AF$2:$AF$250001,"<="&$D6,Data!$AJ$2:$AJ$250001,"Blijft in ziekenhuis") | H6: =IF(COUNT(Data!$AL$2:$AL$250001)=0,"",ROUND(SUMIFS(Data!$AL$2:$AL$250001,Data!$AN$2:$AN$250001,1,Data!$AF$2:$AF$250001,">"&$C6,Data!$AF$2:$AF$250001,"<="&$D6,Data!$AJ$2:$AJ$250001,"Naar huis"),1)) | I6: =IF(COUNTIFS(Data!$AN$2:$AN$250001,1,Data!$AF$2:$AF$250001,">=0")=0,"",COUNTIFS(Data!$AN$2:$AN$250001,1,Data!$AF$2:$AF$250001,">"&$C6,Data!$AF$2:$AF$250001,"<="&$D6)/COUNTIFS(Data!$AN$2:$AN$250001,1,Data!$AF$2:$AF$250001,">=0"))
B7: 2 tot 4 uur | C7: 2 | D7: 4 | E7: =COUNTIFS(Data!$AN$2:$AN$250001,1,Data!$AF$2:$AF$250001,">"&$C7,Data!$AF$2:$AF$250001,"<="&$D7) | F7: =COUNTIFS(Data!$AN$2:$AN$250001,1,Data!$AF$2:$AF$250001,">"&$C7,Data!$AF$2:$AF$250001,"<="&$D7,Data!$AJ$2:$AJ$250001,"Naar huis") | G7: =COUNTIFS(Data!$AN$2:$AN$250001,1,Data!$AF$2:$AF$250001,">"&$C7,Data!$AF$2:$AF$250001,"<="&$D7,Data!$AJ$2:$AJ$250001,"Blijft in ziekenhuis") | H7: =IF(COUNT(Data!$AL$2:$AL$250001)=0,"",ROUND(SUMIFS(Data!$AL$2:$AL$250001,Data!$AN$2:$AN$250001,1,Data!$AF$2:$AF$250001,">"&$C7,Data!$AF$2:$AF$250001,"<="&$D7,Data!$AJ$2:$AJ$250001,"Naar huis"),1)) | I7: =IF(COUNTIFS(Data!$AN$2:$AN$250001,1,Data!$AF$2:$AF$250001,">=0")=0,"",COUNTIFS(Data!$AN$2:$AN$250001,1,Data!$AF$2:$AF$250001,">"&$C7,Data!$AF$2:$AF$250001,"<="&$D7)/COUNTIFS(Data!$AN$2:$AN$250001,1,Data!$AF$2:$AF$250001,">=0"))
B8: 4 tot 6 uur | C8: 4 | D8: 6 | E8: =COUNTIFS(Data!$AN$2:$AN$250001,1,Data!$AF$2:$AF$250001,">"&$C8,Data!$AF$2:$AF$250001,"<="&$D8) | F8: =COUNTIFS(Data!$AN$2:$AN$250001,1,Data!$AF$2:$AF$250001,">"&$C8,Data!$AF$2:$AF$250001,"<="&$D8,Data!$AJ$2:$AJ$250001,"Naar huis") | G8: =COUNTIFS(Data!$AN$2:$AN$250001,1,Data!$AF$2:$AF$250001,">"&$C8,Data!$AF$2:$AF$250001,"<="&$D8,Data!$AJ$2:$AJ$250001,"Blijft in ziekenhuis") | H8: =IF(COUNT(Data!$AL$2:$AL$250001)=0,"",ROUND(SUMIFS(Data!$AL$2:$AL$250001,Data!$AN$2:$AN$250001,1,Data!$AF$2:$AF$250001,">"&$C8,Data!$AF$2:$AF$250001,"<="&$D8,Data!$AJ$2:$AJ$250001,"Naar huis"),1)) | I8: =IF(COUNTIFS(Data!$AN$2:$AN$250001,1,Data!$AF$2:$AF$250001,">=0")=0,"",COUNTIFS(Data!$AN$2:$AN$250001,1,Data!$AF$2:$AF$250001,">"&$C8,Data!$AF$2:$AF$250001,"<="&$D8)/COUNTIFS(Data!$AN$2:$AN$250001,1,Data!$AF$2:$AF$250001,">=0"))
B9: 6 tot 8 uur | C9: 6 | D9: 8 | E9: =COUNTIFS(Data!$AN$2:$AN$250001,1,Data!$AF$2:$AF$250001,">"&$C9,Data!$AF$2:$AF$250001,"<="&$D9) | F9: =COUNTIFS(Data!$AN$2:$AN$250001,1,Data!$AF$2:$AF$250001,">"&$C9,Data!$AF$2:$AF$250001,"<="&$D9,Data!$AJ$2:$AJ$250001,"Naar huis") | G9: =COUNTIFS(Data!$AN$2:$AN$250001,1,Data!$AF$2:$AF$250001,">"&$C9,Data!$AF$2:$AF$250001,"<="&$D9,Data!$AJ$2:$AJ$250001,"Blijft in ziekenhuis") | H9: =IF(COUNT(Data!$AL$2:$AL$250001)=0,"",ROUND(SUMIFS(Data!$AL$2:$AL$250001,Data!$AN$2:$AN$250001,1,Data!$AF$2:$AF$250001,">"&$C9,Data!$AF$2:$AF$250001,"<="&$D9,Data!$AJ$2:$AJ$250001,"Naar huis"),1)) | I9: =IF(COUNTIFS(Data!$AN$2:$AN$250001,1,Data!$AF$2:$AF$250001,">=0")=0,"",COUNTIFS(Data!$AN$2:$AN$250001,1,Data!$AF$2:$AF$250001,">"&$C9,Data!$AF$2:$AF$250001,"<="&$D9)/COUNTIFS(Data!$AN$2:$AN$250001,1,Data!$AF$2:$AF$250001,">=0"))
B10: 8 tot 10 uur | C10: 8 | D10: 10 | E10: =COUNTIFS(Data!$AN$2:$AN$250001,1,Data!$AF$2:$AF$250001,">"&$C10,Data!$AF$2:$AF$250001,"<="&$D10) | F10: =COUNTIFS(Data!$AN$2:$AN$250001,1,Data!$AF$2:$AF$250001,">"&$C10,Data!$AF$2:$AF$250001,"<="&$D10,Data!$AJ$2:$AJ$250001,"Naar huis") | G10: =COUNTIFS(Data!$AN$2:$AN$250001,1,Data!$AF$2:$AF$250001,">"&$C10,Data!$AF$2:$AF$250001,"<="&$D10,Data!$AJ$2:$AJ$250001,"Blijft in ziekenhuis") | H10: =IF(COUNT(Data!$AL$2:$AL$250001)=0,"",ROUND(SUMIFS(Data!$AL$2:$AL$250001,Data!$AN$2:$AN$250001,1,Data!$AF$2:$AF$250001,">"&$C10,Data!$AF$2:$AF$250001,"<="&$D10,Data!$AJ$2:$AJ$250001,"Naar huis"),1)) | I10: =IF(COUNTIFS(Data!$AN$2:$AN$250001,1,Data!$AF$2:$AF$250001,">=0")=0,"",COUNTIFS(Data!$AN$2:$AN$250001,1,Data!$AF$2:$AF$250001,">"&$C10,Data!$AF$2:$AF$250001,"<="&$D10)/COUNTIFS(Data!$AN$2:$AN$250001,1,Data!$AF$2:$AF$250001,">=0"))
B11: 10 tot 12 uur | C11: 10 | D11: 12 | E11: =COUNTIFS(Data!$AN$2:$AN$250001,1,Data!$AF$2:$AF$250001,">"&$C11,Data!$AF$2:$AF$250001,"<="&$D11) | F11: =COUNTIFS(Data!$AN$2:$AN$250001,1,Data!$AF$2:$AF$250001,">"&$C11,Data!$AF$2:$AF$250001,"<="&$D11,Data!$AJ$2:$AJ$250001,"Naar huis") | G11: =COUNTIFS(Data!$AN$2:$AN$250001,1,Data!$AF$2:$AF$250001,">"&$C11,Data!$AF$2:$AF$250001,"<="&$D11,Data!$AJ$2:$AJ$250001,"Blijft in ziekenhuis") | H11: =IF(COUNT(Data!$AL$2:$AL$250001)=0,"",ROUND(SUMIFS(Data!$AL$2:$AL$250001,Data!$AN$2:$AN$250001,1,Data!$AF$2:$AF$250001,">"&$C11,Data!$AF$2:$AF$250001,"<="&$D11,Data!$AJ$2:$AJ$250001,"Naar huis"),1)) | I11: =IF(COUNTIFS(Data!$AN$2:$AN$250001,1,Data!$AF$2:$AF$250001,">=0")=0,"",COUNTIFS(Data!$AN$2:$AN$250001,1,Data!$AF$2:$AF$250001,">"&$C11,Data!$AF$2:$AF$250001,"<="&$D11)/COUNTIFS(Data!$AN$2:$AN$250001,1,Data!$AF$2:$AF$250001,">=0"))
B12: 12 tot 14 uur | C12: 12 | D12: 14 | E12: =COUNTIFS(Data!$AN$2:$AN$250001,1,Data!$AF$2:$AF$250001,">"&$C12,Data!$AF$2:$AF$250001,"<="&$D12) | F12: =COUNTIFS(Data!$AN$2:$AN$250001,1,Data!$AF$2:$AF$250001,">"&$C12,Data!$AF$2:$AF$250001,"<="&$D12,Data!$AJ$2:$AJ$250001,"Naar huis") | G12: =COUNTIFS(Data!$AN$2:$AN$250001,1,Data!$AF$2:$AF$250001,">"&$C12,Data!$AF$2:$AF$250001,"<="&$D12,Data!$AJ$2:$AJ$250001,"Blijft in ziekenhuis") | H12: =IF(COUNT(Data!$AL$2:$AL$250001)=0,"",ROUND(SUMIFS(Data!$AL$2:$AL$250001,Data!$AN$2:$AN$250001,1,Data!$AF$2:$AF$250001,">"&$C12,Data!$AF$2:$AF$250001,"<="&$D12,Data!$AJ$2:$AJ$250001,"Naar huis"),1)) | I12: =IF(COUNTIFS(Data!$AN$2:$AN$250001,1,Data!$AF$2:$AF$250001,">=0")=0,"",COUNTIFS(Data!$AN$2:$AN$250001,1,Data!$AF$2:$AF$250001,">"&$C12,Data!$AF$2:$AF$250001,"<="&$D12)/COUNTIFS(Data!$AN$2:$AN$250001,1,Data!$AF$2:$AF$250001,">=0"))
B13: 14 tot 16 uur | C13: 14 | D13: 16 | E13: =COUNTIFS(Data!$AN$2:$AN$250001,1,Data!$AF$2:$AF$250001,">"&$C13,Data!$AF$2:$AF$250001,"<="&$D13) | F13: =COUNTIFS(Data!$AN$2:$AN$250001,1,Data!$AF$2:$AF$250001,">"&$C13,Data!$AF$2:$AF$250001,"<="&$D13,Data!$AJ$2:$AJ$250001,"Naar huis") | G13: =COUNTIFS(Data!$AN$2:$AN$250001,1,Data!$AF$2:$AF$250001,">"&$C13,Data!$AF$2:$AF$250001,"<="&$D13,Data!$AJ$2:$AJ$250001,"Blijft in ziekenhuis") | H13: =IF(COUNT(Data!$AL$2:$AL$250001)=0,"",ROUND(SUMIFS(Data!$AL$2:$AL$250001,Data!$AN$2:$AN$250001,1,Data!$AF$2:$AF$250001,">"&$C13,Data!$AF$2:$AF$250001,"<="&$D13,Data!$AJ$2:$AJ$250001,"Naar huis"),1)) | I13: =IF(COUNTIFS(Data!$AN$2:$AN$250001,1,Data!$AF$2:$AF$250001,">=0")=0,"",COUNTIFS(Data!$AN$2:$AN$250001,1,Data!$AF$2:$AF$250001,">"&$C13,Data!$AF$2:$AF$250001,"<="&$D13)/COUNTIFS(Data!$AN$2:$AN$250001,1,Data!$AF$2:$AF$250001,">=0"))
B14: 16 tot 18 uur | C14: 16 | D14: 18 | E14: =COUNTIFS(Data!$AN$2:$AN$250001,1,Data!$AF$2:$AF$250001,">"&$C14,Data!$AF$2:$AF$250001,"<="&$D14) | F14: =COUNTIFS(Data!$AN$2:$AN$250001,1,Data!$AF$2:$AF$250001,">"&$C14,Data!$AF$2:$AF$250001,"<="&$D14,Data!$AJ$2:$AJ$250001,"Naar huis") | G14: =COUNTIFS(Data!$AN$2:$AN$250001,1,Data!$AF$2:$AF$250001,">"&$C14,Data!$AF$2:$AF$250001,"<="&$D14,Data!$AJ$2:$AJ$250001,"Blijft in ziekenhuis") | H14: =IF(COUNT(Data!$AL$2:$AL$250001)=0,"",ROUND(SUMIFS(Data!$AL$2:$AL$250001,Data!$AN$2:$AN$250001,1,Data!$AF$2:$AF$250001,">"&$C14,Data!$AF$2:$AF$250001,"<="&$D14,Data!$AJ$2:$AJ$250001,"Naar huis"),1)) | I14: =IF(COUNTIFS(Data!$AN$2:$AN$250001,1,Data!$AF$2:$AF$250001,">=0")=0,"",COUNTIFS(Data!$AN$2:$AN$250001,1,Data!$AF$2:$AF$250001,">"&$C14,Data!$AF$2:$AF$250001,"<="&$D14)/COUNTIFS(Data!$AN$2:$AN$250001,1,Data!$AF$2:$AF$250001,">=0"))
B15: 18 tot 20 uur | C15: 18 | D15: 20 | E15: =COUNTIFS(Data!$AN$2:$AN$250001,1,Data!$AF$2:$AF$250001,">"&$C15,Data!$AF$2:$AF$250001,"<="&$D15) | F15: =COUNTIFS(Data!$AN$2:$AN$250001,1,Data!$AF$2:$AF$250001,">"&$C15,Data!$AF$2:$AF$250001,"<="&$D15,Data!$AJ$2:$AJ$250001,"Naar huis") | G15: =COUNTIFS(Data!$AN$2:$AN$250001,1,Data!$AF$2:$AF$250001,">"&$C15,Data!$AF$2:$AF$250001,"<="&$D15,Data!$AJ$2:$AJ$250001,"Blijft in ziekenhuis") | H15: =IF(COUNT(Data!$AL$2:$AL$250001)=0,"",ROUND(SUMIFS(Data!$AL$2:$AL$250001,Data!$AN$2:$AN$250001,1,Data!$AF$2:$AF$250001,">"&$C15,Data!$AF$2:$AF$250001,"<="&$D15,Data!$AJ$2:$AJ$250001,"Naar huis"),1)) | I15: =IF(COUNTIFS(Data!$AN$2:$AN$250001,1,Data!$AF$2:$AF$250001,">=0")=0,"",COUNTIFS(Data!$AN$2:$AN$250001,1,Data!$AF$2:$AF$250001,">"&$C15,Data!$AF$2:$AF$250001,"<="&$D15)/COUNTIFS(Data!$AN$2:$AN$250001,1,Data!$AF$2:$AF$250001,">=0"))
B16: 20 tot 22 uur | C16: 20 | D16: 22 | E16: =COUNTIFS(Data!$AN$2:$AN$250001,1,Data!$AF$2:$AF$250001,">"&$C16,Data!$AF$2:$AF$250001,"<="&$D16) | F16: =COUNTIFS(Data!$AN$2:$AN$250001,1,Data!$AF$2:$AF$250001,">"&$C16,Data!$AF$2:$AF$250001,"<="&$D16,Data!$AJ$2:$AJ$250001,"Naar huis") | G16: =COUNTIFS(Data!$AN$2:$AN$250001,1,Data!$AF$2:$AF$250001,">"&$C16,Data!$AF$2:$AF$250001,"<="&$D16,Data!$AJ$2:$AJ$250001,"Blijft in ziekenhuis") | H16: =IF(COUNT(Data!$AL$2:$AL$250001)=0,"",ROUND(SUMIFS(Data!$AL$2:$AL$250001,Data!$AN$2:$AN$250001,1,Data!$AF$2:$AF$250001,">"&$C16,Data!$AF$2:$AF$250001,"<="&$D16,Data!$AJ$2:$AJ$250001,"Naar huis"),1)) | I16: =IF(COUNTIFS(Data!$AN$2:$AN$250001,1,Data!$AF$2:$AF$250001,">=0")=0,"",COUNTIFS(Data!$AN$2:$AN$250001,1,Data!$AF$2:$AF$250001,">"&$C16,Data!$AF$2:$AF$250001,"<="&$D16)/COUNTIFS(Data!$AN$2:$AN$250001,1,Data!$AF$2:$AF$250001,">=0"))
B17: 22 tot 24 uur | C17: 22 | D17: 24 | E17: =COUNTIFS(Data!$AN$2:$AN$250001,1,Data!$AF$2:$AF$250001,">"&$C17,Data!$AF$2:$AF$250001,"<="&$D17) | F17: =COUNTIFS(Data!$AN$2:$AN$250001,1,Data!$AF$2:$AF$250001,">"&$C17,Data!$AF$2:$AF$250001,"<="&$D17,Data!$AJ$2:$AJ$250001,"Naar huis") | G17: =COUNTIFS(Data!$AN$2:$AN$250001,1,Data!$AF$2:$AF$250001,">"&$C17,Data!$AF$2:$AF$250001,"<="&$D17,Data!$AJ$2:$AJ$250001,"Blijft in ziekenhuis") | H17: =IF(COUNT(Data!$AL$2:$AL$250001)=0,"",ROUND(SUMIFS(Data!$AL$2:$AL$250001,Data!$AN$2:$AN$250001,1,Data!$AF$2:$AF$250001,">"&$C17,Data!$AF$2:$AF$250001,"<="&$D17,Data!$AJ$2:$AJ$250001,"Naar huis"),1)) | I17: =IF(COUNTIFS(Data!$AN$2:$AN$250001,1,Data!$AF$2:$AF$250001,">=0")=0,"",COUNTIFS(Data!$AN$2:$AN$250001,1,Data!$AF$2:$AF$250001,">"&$C17,Data!$AF$2:$AF$250001,"<="&$D17)/COUNTIFS(Data!$AN$2:$AN$250001,1,Data!$AF$2:$AF$250001,">=0"))
B18: Meer dan 24 uur | C18: 24 | E18: =COUNTIFS(Data!$AN$2:$AN$250001,1,Data!$AF$2:$AF$250001,">24") | F18: =COUNTIFS(Data!$AN$2:$AN$250001,1,Data!$AF$2:$AF$250001,">24",Data!$AJ$2:$AJ$250001,"Naar huis") | G18: =COUNTIFS(Data!$AN$2:$AN$250001,1,Data!$AF$2:$AF$250001,">24",Data!$AJ$2:$AJ$250001,"Blijft in ziekenhuis") | H18: =IF(COUNT(Data!$AL$2:$AL$250001)=0,"",ROUND(SUMIFS(Data!$AL$2:$AL$250001,Data!$AN$2:$AN$250001,1,Data!$AF$2:$AF$250001,">24",Data!$AJ$2:$AJ$250001,"Naar huis"),1)) | I18: =IF(COUNTIFS(Data!$AN$2:$AN$250001,1,Data!$AF$2:$AF$250001,">=0")=0,"",COUNTIFS(Data!$AN$2:$AN$250001,1,Data!$AF$2:$AF$250001,">24")/COUNTIFS(Data!$AN$2:$AN$250001,1,Data!$AF$2:$AF$250001,">=0"))
B19: Totaal | E19: =SUM(E6:E18) | F19: =SUM(F6:F18) | G19: =SUM(G6:G18) | H19: =SUM(H6:H18) | I19: =IF(COUNTIFS(Data!$AN$2:$AN$250001,1,Data!$AF$2:$AF$250001,">=0")=0,"",SUM(E6:E18)/COUNTIFS(Data!$AN$2:$AN$250001,1,Data!$AF$2:$AF$250001,">=0"))
B21: De blokken tellen 'groter dan vanaf' tot en met 'tot'. Een opname van precies 6,0 uur valt dus in 4 tot 6 uur en niet in de selectie.
