Workbook

Sheet Leesmij
B2: SEH – Analyse langliggers (> 4 uur) versus werkdruk / bezetting
B4: Doel: inzicht of de ligduur toeneemt naarmate de werkdruk op de regievoerend SEH-arts toeneemt.
B5: Dit werkboek berekent HOEVEEL patiënten er tegelijk aanwezig zijn (bezetting), gesplitst naar langliggers en het totaal. Zo koppel je de langliggers aan de drukte én aan je artsenbezetting.
B6: We rekenen NIET met gemiddelden maar met het 95e PERCENTIEL (P95) = het niveau op de drukke momenten: 95% van de tijd is het niet drukker dan dit getal. Een getal '3' bij maandag 14 uur betekent dus: op een drukke maandag liggen er rond 14 uur zo'n 3 langliggers tegelijk.
B8: ZO GEBRUIK JE HET (3 stappen)
B9: 1. Plak je VOLLEDIGE patiëntenlijst (alle patiënten, NIET gefilterd) in tabblad 'Data', vanaf rij 2, ín de tabel zodat hij meegroeit. Plak ALLEEN de gegevens (niet de kopregel). De kolomvolgorde is gelijk aan jouw export; de hulpkolommen (X t/m AE) vullen zich vanzelf aan.
B10: → Nieuw: kolom 'SpecialismeCodeIntern' (naast de artsnaam) met de afkorting van het specialisme (SEH, MDL, LONG, …). Controleer of de kolomvolgorde klopt met jouw export en versleep zo nodig kolommen.
B11: → Je hoeft GEEN aparte gefilterde langliggerslijst te plakken. De langliggers worden automatisch afgeleid uit de ligduur. Zo lopen totaal en langliggers nooit uit de pas.
B12: 2. Controleer in 'Instellingen' de drempel voor langligger (standaard 240 min = 4 uur). De gele cel is de enige instelcel.
B13: 3. Bekijk de antwoorden. Begin op tabblad 'Grafieken' (kies een dag en zie per uur de langliggers t.o.v. de overige patiënten, plus een vergelijking tussen de dagen). De tabbladen 'Q1/Q2/Q3' bevatten dezelfde cijfers als tabel, voor wie liever de getallen ziet. Alles herrekent automatisch (druk zo nodig op F9).
B15: BELANGRIJK VOOR DE BEREKENING
B16: • 'Start' (kolom S) en 'Eind' (kolom T) moeten ECHTE datum-tijd-waarden zijn (geen tekst). Rechts uitgelijnd = goed; links uitgelijnd = tekst, eerst omzetten.
... B29: Kleuren: GEEL = zelf invullen/instellen · ORANJE = voorbeeldregel (overschrijven of verwijderen) · blauw lettertype = invoer.

Sheet Data
A1: AfdelingLabel | B1: SEHTrajectPeriodeIDIntern | C1: SEHTrajectIDIntern | D1: Jaar | E1: WeekNummer | F1: CodePreferent | G1: SEHTrajectPeriodeDatumTijdVan | H1: SEHTrajectPeriodeDatumTijdTotEnMet | I1: SEHTrajectKlachtOmschrijving | J1: Omschrijving | K1: OmschrijvingIntern | L1: SpecialismeLabelIntern | M1: SEH specialist | N1: SpecialismeCodeIntern | O1: Aantal | P1: Aantal_Minuten | Q1: Urgentiecategory | R1: Fasttrack/ RAD geincludeerd | S1: Start | T1: Eind | U1: Minuten | V1: Uren | W1: Langer dan 4 uur | X1: Duur_min | Y1: Langligger | Z1: EersteRegelBezoek | AA1: BezoekStart | AB1: BezoekEind | AC1: BezoekLanglig | AD1: BezoekLangStart | AE1: BezoekLangEind
A2: SEH | B2: 1001 | C2: 5001 | D2: 2025 | E2: 24 | F2: 123456 | G2: 45818.583 | H2: 45818.812 | I2: Pijn op de borst | J2: Thoraxpijn | K2: ACS-analyse | L2: Cardiologie | M2: Dr. Jansen | N2: SEH | O2: 1 | P2: 330 | Q2: U2 | R2: Nee | S2: 45818.583 | T2: 45818.812 | U2: 330 | V2: 5.5 | W2: Ja | X2: =IF(OR($S2="",$T2=""),"",($T2-$S2)*1440) | Y2: =IF($X2="","",IF($X2>Instellingen!$B$3,1,0)) | Z2: =IF($B2="","",IF(COUNTIF($B$2:$B2,$B2)=1,1,0)) | AA2: =IF($Z2=1,_xlfn.MINIFS(tData[Start],tData[SEHTrajectPeriodeIDIntern],$B2),"") | AB2: =IF($Z2=1,_xlfn.MAXIFS(tData[Eind],tData[SEHTrajectPeriodeIDIntern],$B2),"") | AC2: =IF($Z2=1,IF(($AB2-$AA2)*1440>Instellingen!$B$3,1,0),"") | AD2: =IF($AC2=1,$AA2,"") | AE2: =IF($AC2=1,$AB2,"")

Sheet Grafieken
A1: Langliggers per uur — antwoord op vraag 1 en 2 | AB1: maandag
A2: Kies een dag (cel B4). De 1e grafiek toont per uur hoeveel langliggers (rood) en hoeveel overige patiënten (grijs) er tegelijk liggen; samen is dat de drukte. Daaronder: het aandeel langliggers, en een vergelijking tussen alle dagen. | AB2: dinsdag
A3: Alle getallen zijn het 95e PERCENTIEL (P95) = het niveau op de drukke momenten: 95% van de tijd is het niet drukker dan dit. Dus geen gemiddelde, maar 'hoe druk het op een drukke dag is'. | AB3: woensdag
A4: Kies een dag: | B4: maandag | AB4: donderdag
A5: Op de drukke momenten (P95) liggen er tot: | AB5: vrijdag
A6: langliggers tegelijk → | C6: =MAX('Q1_Verdeling'!$C$5:$Z$11) | D6: patiënten tegelijk (totaal) → | F6: =MAX('Q2_Ratio'!$C$5:$Z$11) | AB6: zaterdag
AB7: zondag
AB8: =MATCH($B$4,$AB$1:$AB$7,0)

Sheet Q1_Verdeling
A1: Vraag 1 – Langliggers per weekdag en uur (95e percentiel)
A2: Op een DRUKKE dag: hoeveel langliggers liggen er tegelijk, per weekdag en uur? Getal = 95e percentiel (P95): 95% van de tijd niet meer dan dit. Donkerder = drukker. Leg dit naast je artsenbezetting.
A4: wd | B4: Weekdag \ Uur | C4: 0 | D4: 1 | E4: 2 | F4: 3 | G4: 4 | H4: 5 | I4: 6 | J4: 7 | K4: 8 | L4: 9 | M4: 10 | N4: 11 | O4: 12 | P4: 13 | Q4: 14 | R4: 15 | S4: 16 | T4: 17 | U4: 18 | V4: 19 | W4: 20 | X4: 21 | Y4: 22 | Z4: 23 | AA4: Hele dag
A5: 1 | B5: maandag | C5: {=IFERROR(PERCENTILE(IF(Tijdlijn!$G$3:$G$17546=$A5*100+C$4,Tijdlijn!$F$3:$F$17546),Instellingen!$B$4),"")} | D5: {=IFERROR(PERCENTILE(IF(Tijdlijn!$G$3:$G$17546=$A5*100+D$4,Tijdlijn!$F$3:$F$17546),Instellingen!$B$4),"")} | E5: {=IFERROR(PERCENTILE(IF(Tijdlijn!$G$3:$G$17546=$A5*100+E$4,Tijdlijn!$F$3:$F$17546),Instellingen!$B$4),"")} | F5: {=IFERROR(PERCENTILE(IF(Tijdlijn!$G$3:$G$17546=$A5*100+F$4,Tijdlijn!$F$3:$F$17546),Instellingen!$B$4),"")} | G5: {=IFERROR(PERCENTILE(IF(Tijdlijn!$G$3:$G$17546=$A5*100+G$4,Tijdlijn!$F$3:$F$17546),Instellingen!$B$4),"")} | H5: {=IFERROR(PERCENTILE(IF(Tijdlijn!$G$3:$G$17546=$A5*100+H$4,Tijdlijn!$F$3:$F$17546),Instellingen!$B$4),"")} | I5: {=IFERROR(PERCENTILE(IF(Tijdlijn!$G$3:$G$17546=$A5*100+I$4,Tijdlijn!$F$3:$F$17546),Instellingen!$B$4),"")} | J5: {=IFERROR(PERCENTILE(IF(Tijdlijn!$G$3:$G$17546=$A5*100+J$4,Tijdlijn!$F$3:$F$17546),Instellingen!$B$4),"")} | ... Z5: {=IFERROR(PERCENTILE(IF(Tijdlijn!$G$3:$G$17546=$A5*100+Z$4,Tijdlijn!$F$3:$F$17546),Instellingen!$B$4),"")} | AA5: {=IFERROR(PERCENTILE(IF(Tijdlijn!$H$3:$H$17546=$A5,Tijdlijn!$F$3:$F$17546),Instellingen!$B$4),"")}
A6: 2 | B6: dinsdag | C6: {=IFERROR(PERCENTILE(IF(Tijdlijn!$G$3:$G$17546=$A6*100+C$4,Tijdlijn!$F$3:$F$17546),Instellingen!$B$4),"")} | D6: {=IFERROR(PERCENTILE(IF(Tijdlijn!$G$3:$G$17546=$A6*100+D$4,Tijdlijn!$F$3:$F$17546),Instellingen!$B$4),"")} | E6: {=IFERROR(PERCENTILE(IF(Tijdlijn!$G$3:$G$17546=$A6*100+E$4,Tijdlijn!$F$3:$F$17546),Instellingen!$B$4),"")} | F6: {=IFERROR(PERCENTILE(IF(Tijdlijn!$G$3:$G$17546=$A6*100+F$4,Tijdlijn!$F$3:$F$17546),Instellingen!$B$4),"")} | G6: {=IFERROR(PERCENTILE(IF(Tijdlijn!$G$3:$G$17546=$A6*100+G$4,Tijdlijn!$F$3:$F$17546),Instellingen!$B$4),"")} | H6: {=IFERROR(PERCENTILE(IF(Tijdlijn!$G$3:$G$17546=$A6*100+H$4,Tijdlijn!$F$3:$F$17546),Instellingen!$B$4),"")} | I6: {=IFERROR(PERCENTILE(IF(Tijdlijn!$G$3:$G$17546=$A6*100+I$4,Tijdlijn!$F$3:$F$17546),Instellingen!$B$4),"")} | J6: {=IFERROR(PERCENTILE(IF(Tijdlijn!$G$3:$G$17546=$A6*100+J$4,Tijdlijn!$F$3:$F$17546),Instellingen!$B$4),"")} | ... Z6: {=IFERROR(PERCENTILE(IF(Tijdlijn!$G$3:$G$17546=$A6*100+Z$4,Tijdlijn!$F$3:$F$17546),Instellingen!$B$4),"")} | AA6: {=IFERROR(PERCENTILE(IF(Tijdlijn!$H$3:$H$17546=$A6,Tijdlijn!$F$3:$F$17546),Instellingen!$B$4),"")}
A7: 3 | B7: woensdag | C7: {=IFERROR(PERCENTILE(IF(Tijdlijn!$G$3:$G$17546=$A7*100+C$4,Tijdlijn!$F$3:$F$17546),Instellingen!$B$4),"")} | D7: {=IFERROR(PERCENTILE(IF(Tijdlijn!$G$3:$G$17546=$A7*100+D$4,Tijdlijn!$F$3:$F$17546),Instellingen!$B$4),"")} | E7: {=IFERROR(PERCENTILE(IF(Tijdlijn!$G$3:$G$17546=$A7*100+E$4,Tijdlijn!$F$3:$F$17546),Instellingen!$B$4),"")} | F7: {=IFERROR(PERCENTILE(IF(Tijdlijn!$G$3:$G$17546=$A7*100+F$4,Tijdlijn!$F$3:$F$17546),Instellingen!$B$4),"")} | G7: {=IFERROR(PERCENTILE(IF(Tijdlijn!$G$3:$G$17546=$A7*100+G$4,Tijdlijn!$F$3:$F$17546),Instellingen!$B$4),"")} | H7: {=IFERROR(PERCENTILE(IF(Tijdlijn!$G$3:$G$17546=$A7*100+H$4,Tijdlijn!$F$3:$F$17546),Instellingen!$B$4),"")} | I7: {=IFERROR(PERCENTILE(IF(Tijdlijn!$G$3:$G$17546=$A7*100+I$4,Tijdlijn!$F$3:$F$17546),Instellingen!$B$4),"")} | J7: {=IFERROR(PERCENTILE(IF(Tijdlijn!$G$3:$G$17546=$A7*100+J$4,Tijdlijn!$F$3:$F$17546),Instellingen!$B$4),"")} | ... Z7: {=IFERROR(PERCENTILE(IF(Tijdlijn!$G$3:$G$17546=$A7*100+Z$4,Tijdlijn!$F$3:$F$17546),Instellingen!$B$4),"")} | AA7: {=IFERROR(PERCENTILE(IF(Tijdlijn!$H$3:$H$17546=$A7,Tijdlijn!$F$3:$F$17546),Instellingen!$B$4),"")}
A8: 4 | B8: donderdag | C8: {=IFERROR(PERCENTILE(IF(Tijdlijn!$G$3:$G$17546=$A8*100+C$4,Tijdlijn!$F$3:$F$17546),Instellingen!$B$4),"")} | D8: {=IFERROR(PERCENTILE(IF(Tijdlijn!$G$3:$G$17546=$A8*100+D$4,Tijdlijn!$F$3:$F$17546),Instellingen!$B$4),"")} | E8: {=IFERROR(PERCENTILE(IF(Tijdlijn!$G$3:$G$17546=$A8*100+E$4,Tijdlijn!$F$3:$F$17546),Instellingen!$B$4),"")} | F8: {=IFERROR(PERCENTILE(IF(Tijdlijn!$G$3:$G$17546=$A8*100+F$4,Tijdlijn!$F$3:$F$17546),Instellingen!$B$4),"")} | G8: {=IFERROR(PERCENTILE(IF(Tijdlijn!$G$3:$G$17546=$A8*100+G$4,Tijdlijn!$F$3:$F$17546),Instellingen!$B$4),"")} | H8: {=IFERROR(PERCENTILE(IF(Tijdlijn!$G$3:$G$17546=$A8*100+H$4,Tijdlijn!$F$3:$F$17546),Instellingen!$B$4),"")} | I8: {=IFERROR(PERCENTILE(IF(Tijdlijn!$G$3:$G$17546=$A8*100+I$4,Tijdlijn!$F$3:$F$17546),Instellingen!$B$4),"")} | J8: {=IFERROR(PERCENTILE(IF(Tijdlijn!$G$3:$G$17546=$A8*100+J$4,Tijdlijn!$F$3:$F$17546),Instellingen!$B$4),"")} | ... Z8: {=IFERROR(PERCENTILE(IF(Tijdlijn!$G$3:$G$17546=$A8*100+Z$4,Tijdlijn!$F$3:$F$17546),Instellingen!$B$4),"")} | AA8: {=IFERROR(PERCENTILE(IF(Tijdlijn!$H$3:$H$17546=$A8,Tijdlijn!$F$3:$F$17546),Instellingen!$B$4),"")}
A9: 5 | B9: vrijdag | C9: {=IFERROR(PERCENTILE(IF(Tijdlijn!$G$3:$G$17546=$A9*100+C$4,Tijdlijn!$F$3:$F$17546),Instellingen!$B$4),"")} | D9: {=IFERROR(PERCENTILE(IF(Tijdlijn!$G$3:$G$17546=$A9*100+D$4,Tijdlijn!$F$3:$F$17546),Instellingen!$B$4),"")} | E9: {=IFERROR(PERCENTILE(IF(Tijdlijn!$G$3:$G$17546=$A9*100+E$4,Tijdlijn!$F$3:$F$17546),Instellingen!$B$4),"")} | F9: {=IFERROR(PERCENTILE(IF(Tijdlijn!$G$3:$G$17546=$A9*100+F$4,Tijdlijn!$F$3:$F$17546),Instellingen!$B$4),"")} | G9: {=IFERROR(PERCENTILE(IF(Tijdlijn!$G$3:$G$17546=$A9*100+G$4,Tijdlijn!$F$3:$F$17546),Instellingen!$B$4),"")} | H9: {=IFERROR(PERCENTILE(IF(Tijdlijn!$G$3:$G$17546=$A9*100+H$4,Tijdlijn!$F$3:$F$17546),Instellingen!$B$4),"")} | I9: {=IFERROR(PERCENTILE(IF(Tijdlijn!$G$3:$G$17546=$A9*100+I$4,Tijdlijn!$F$3:$F$17546),Instellingen!$B$4),"")} | J9: {=IFERROR(PERCENTILE(IF(Tijdlijn!$G$3:$G$17546=$A9*100+J$4,Tijdlijn!$F$3:$F$17546),Instellingen!$B$4),"")} | ... Z9: {=IFERROR(PERCENTILE(IF(Tijdlijn!$G$3:$G$17546=$A9*100+Z$4,Tijdlijn!$F$3:$F$17546),Instellingen!$B$4),"")} | AA9: {=IFERROR(PERCENTILE(IF(Tijdlijn!$H$3:$H$17546=$A9,Tijdlijn!$F$3:$F$17546),Instellingen!$B$4),"")}
A10: 6 | B10: zaterdag | C10: {=IFERROR(PERCENTILE(IF(Tijdlijn!$G$3:$G$17546=$A10*100+C$4,Tijdlijn!$F$3:$F$17546),Instellingen!$B$4),"")} | D10: {=IFERROR(PERCENTILE(IF(Tijdlijn!$G$3:$G$17546=$A10*100+D$4,Tijdlijn!$F$3:$F$17546),Instellingen!$B$4),"")} | E10: {=IFERROR(PERCENTILE(IF(Tijdlijn!$G$3:$G$17546=$A10*100+E$4,Tijdlijn!$F$3:$F$17546),Instellingen!$B$4),"")} | F10: {=IFERROR(PERCENTILE(IF(Tijdlijn!$G$3:$G$17546=$A10*100+F$4,Tijdlijn!$F$3:$F$17546),Instellingen!$B$4),"")} | G10: {=IFERROR(PERCENTILE(IF(Tijdlijn!$G$3:$G$17546=$A10*100+G$4,Tijdlijn!$F$3:$F$17546),Instellingen!$B$4),"")} | H10: {=IFERROR(PERCENTILE(IF(Tijdlijn!$G$3:$G$17546=$A10*100+H$4,Tijdlijn!$F$3:$F$17546),Instellingen!$B$4),"")} | I10: {=IFERROR(PERCENTILE(IF(Tijdlijn!$G$3:$G$17546=$A10*100+I$4,Tijdlijn!$F$3:$F$17546),Instellingen!$B$4),"")} | J10: {=IFERROR(PERCENTILE(IF(Tijdlijn!$G$3:$G$17546=$A10*100+J$4,Tijdlijn!$F$3:$F$17546),Instellingen!$B$4),"")} | ... Z10: {=IFERROR(PERCENTILE(IF(Tijdlijn!$G$3:$G$17546=$A10*100+Z$4,Tijdlijn!$F$3:$F$17546),Instellingen!$B$4),"")} | AA10: {=IFERROR(PERCENTILE(IF(Tijdlijn!$H$3:$H$17546=$A10,Tijdlijn!$F$3:$F$17546),Instellingen!$B$4),"")}
A11: 7 | B11: zondag | C11: {=IFERROR(PERCENTILE(IF(Tijdlijn!$G$3:$G$17546=$A11*100+C$4,Tijdlijn!$F$3:$F$17546),Instellingen!$B$4),"")} | D11: {=IFERROR(PERCENTILE(IF(Tijdlijn!$G$3:$G$17546=$A11*100+D$4,Tijdlijn!$F$3:$F$17546),Instellingen!$B$4),"")} | E11: {=IFERROR(PERCENTILE(IF(Tijdlijn!$G$3:$G$17546=$A11*100+E$4,Tijdlijn!$F$3:$F$17546),Instellingen!$B$4),"")} | F11: {=IFERROR(PERCENTILE(IF(Tijdlijn!$G$3:$G$17546=$A11*100+F$4,Tijdlijn!$F$3:$F$17546),Instellingen!$B$4),"")} | G11: {=IFERROR(PERCENTILE(IF(Tijdlijn!$G$3:$G$17546=$A11*100+G$4,Tijdlijn!$F$3:$F$17546),Instellingen!$B$4),"")} | H11: {=IFERROR(PERCENTILE(IF(Tijdlijn!$G$3:$G$17546=$A11*100+H$4,Tijdlijn!$F$3:$F$17546),Instellingen!$B$4),"")} | I11: {=IFERROR(PERCENTILE(IF(Tijdlijn!$G$3:$G$17546=$A11*100+I$4,Tijdlijn!$F$3:$F$17546),Instellingen!$B$4),"")} | J11: {=IFERROR(PERCENTILE(IF(Tijdlijn!$G$3:$G$17546=$A11*100+J$4,Tijdlijn!$F$3:$F$17546),Instellingen!$B$4),"")} | ... Z11: {=IFERROR(PERCENTILE(IF(Tijdlijn!$G$3:$G$17546=$A11*100+Z$4,Tijdlijn!$F$3:$F$17546),Instellingen!$B$4),"")} | AA11: {=IFERROR(PERCENTILE(IF(Tijdlijn!$H$3:$H$17546=$A11,Tijdlijn!$F$3:$F$17546),Instellingen!$B$4),"")}
B12: Alle dagen | C12: {=IFERROR(PERCENTILE(IF(Tijdlijn!$I$3:$I$17546=C$4,Tijdlijn!$F$3:$F$17546),Instellingen!$B$4),"")} | D12: {=IFERROR(PERCENTILE(IF(Tijdlijn!$I$3:$I$17546=D$4,Tijdlijn!$F$3:$F$17546),Instellingen!$B$4),"")} | E12: {=IFERROR(PERCENTILE(IF(Tijdlijn!$I$3:$I$17546=E$4,Tijdlijn!$F$3:$F$17546),Instellingen!$B$4),"")} | F12: {=IFERROR(PERCENTILE(IF(Tijdlijn!$I$3:$I$17546=F$4,Tijdlijn!$F$3:$F$17546),Instellingen!$B$4),"")} | G12: {=IFERROR(PERCENTILE(IF(Tijdlijn!$I$3:$I$17546=G$4,Tijdlijn!$F$3:$F$17546),Instellingen!$B$4),"")} | H12: {=IFERROR(PERCENTILE(IF(Tijdlijn!$I$3:$I$17546=H$4,Tijdlijn!$F$3:$F$17546),Instellingen!$B$4),"")} | I12: {=IFERROR(PERCENTILE(IF(Tijdlijn!$I$3:$I$17546=I$4,Tijdlijn!$F$3:$F$17546),Instellingen!$B$4),"")} | J12: {=IFERROR(PERCENTILE(IF(Tijdlijn!$I$3:$I$17546=J$4,Tijdlijn!$F$3:$F$17546),Instellingen!$B$4),"")} | ... Z12: {=IFERROR(PERCENTILE(IF(Tijdlijn!$I$3:$I$17546=Z$4,Tijdlijn!$F$3:$F$17546),Instellingen!$B$4),"")} | AA12: {=IFERROR(PERCENTILE(IF(Tijdlijn!$D$3:$D$17546=1,Tijdlijn!$F$3:$F$17546),Instellingen!$B$4),"")}

Sheet Q2_Ratio
A1: Vraag 2 – Totaal aanwezige patiënten per weekdag en uur (95e percentiel)
A2: Op een DRUKKE dag: hoeveel patiënten liggen er in totaal tegelijk (= de drukte)? Getal = 95e percentiel. Hieronder het aandeel dat langligger is.
A4: wd | B4: Weekdag \ Uur | C4: 0 | D4: 1 | E4: 2 | F4: 3 | G4: 4 | H4: 5 | I4: 6 | J4: 7 | K4: 8 | L4: 9 | M4: 10 | N4: 11 | O4: 12 | P4: 13 | Q4: 14 | R4: 15 | S4: 16 | T4: 17 | U4: 18 | V4: 19 | W4: 20 | X4: 21 | Y4: 22 | Z4: 23 | AA4: Hele dag
A5: 1 | B5: maandag | C5: {=IFERROR(PERCENTILE(IF(Tijdlijn!$G$3:$G$17546=$A5*100+C$4,Tijdlijn!$E$3:$E$17546),Instellingen!$B$4),"")} | D5: {=IFERROR(PERCENTILE(IF(Tijdlijn!$G$3:$G$17546=$A5*100+D$4,Tijdlijn!$E$3:$E$17546),Instellingen!$B$4),"")} | E5: {=IFERROR(PERCENTILE(IF(Tijdlijn!$G$3:$G$17546=$A5*100+E$4,Tijdlijn!$E$3:$E$17546),Instellingen!$B$4),"")} | F5: {=IFERROR(PERCENTILE(IF(Tijdlijn!$G$3:$G$17546=$A5*100+F$4,Tijdlijn!$E$3:$E$17546),Instellingen!$B$4),"")} | G5: {=IFERROR(PERCENTILE(IF(Tijdlijn!$G$3:$G$17546=$A5*100+G$4,Tijdlijn!$E$3:$E$17546),Instellingen!$B$4),"")} | H5: {=IFERROR(PERCENTILE(IF(Tijdlijn!$G$3:$G$17546=$A5*100+H$4,Tijdlijn!$E$3:$E$17546),Instellingen!$B$4),"")} | I5: {=IFERROR(PERCENTILE(IF(Tijdlijn!$G$3:$G$17546=$A5*100+I$4,Tijdlijn!$E$3:$E$17546),Instellingen!$B$4),"")} | J5: {=IFERROR(PERCENTILE(IF(Tijdlijn!$G$3:$G$17546=$A5*100+J$4,Tijdlijn!$E$3:$E$17546),Instellingen!$B$4),"")} | ... Z5: {=IFERROR(PERCENTILE(IF(Tijdlijn!$G$3:$G$17546=$A5*100+Z$4,Tijdlijn!$E$3:$E$17546),Instellingen!$B$4),"")} | AA5: {=IFERROR(PERCENTILE(IF(Tijdlijn!$H$3:$H$17546=$A5,Tijdlijn!$E$3:$E$17546),Instellingen!$B$4),"")}
A6: 2 | B6: dinsdag | C6: {=IFERROR(PERCENTILE(IF(Tijdlijn!$G$3:$G$17546=$A6*100+C$4,Tijdlijn!$E$3:$E$17546),Instellingen!$B$4),"")} | D6: {=IFERROR(PERCENTILE(IF(Tijdlijn!$G$3:$G$17546=$A6*100+D$4,Tijdlijn!$E$3:$E$17546),Instellingen!$B$4),"")} | E6: {=IFERROR(PERCENTILE(IF(Tijdlijn!$G$3:$G$17546=$A6*100+E$4,Tijdlijn!$E$3:$E$17546),Instellingen!$B$4),"")} | F6: {=IFERROR(PERCENTILE(IF(Tijdlijn!$G$3:$G$17546=$A6*100+F$4,Tijdlijn!$E$3:$E$17546),Instellingen!$B$4),"")} | G6: {=IFERROR(PERCENTILE(IF(Tijdlijn!$G$3:$G$17546=$A6*100+G$4,Tijdlijn!$E$3:$E$17546),Instellingen!$B$4),"")} | H6: {=IFERROR(PERCENTILE(IF(Tijdlijn!$G$3:$G$17546=$A6*100+H$4,Tijdlijn!$E$3:$E$17546),Instellingen!$B$4),"")} | I6: {=IFERROR(PERCENTILE(IF(Tijdlijn!$G$3:$G$17546=$A6*100+I$4,Tijdlijn!$E$3:$E$17546),Instellingen!$B$4),"")} | J6: {=IFERROR(PERCENTILE(IF(Tijdlijn!$G$3:$G$17546=$A6*100+J$4,Tijdlijn!$E$3:$E$17546),Instellingen!$B$4),"")} | ... Z6: {=IFERROR(PERCENTILE(IF(Tijdlijn!$G$3:$G$17546=$A6*100+Z$4,Tijdlijn!$E$3:$E$17546),Instellingen!$B$4),"")} | AA6: {=IFERROR(PERCENTILE(IF(Tijdlijn!$H$3:$H$17546=$A6,Tijdlijn!$E$3:$E$17546),Instellingen!$B$4),"")}
A7: 3 | B7: woensdag | C7: {=IFERROR(PERCENTILE(IF(Tijdlijn!$G$3:$G$17546=$A7*100+C$4,Tijdlijn!$E$3:$E$17546),Instellingen!$B$4),"")} | D7: {=IFERROR(PERCENTILE(IF(Tijdlijn!$G$3:$G$17546=$A7*100+D$4,Tijdlijn!$E$3:$E$17546),Instellingen!$B$4),"")} | E7: {=IFERROR(PERCENTILE(IF(Tijdlijn!$G$3:$G$17546=$A7*100+E$4,Tijdlijn!$E$3:$E$17546),Instellingen!$B$4),"")} | F7: {=IFERROR(PERCENTILE(IF(Tijdlijn!$G$3:$G$17546=$A7*100+F$4,Tijdlijn!$E$3:$E$17546),Instellingen!$B$4),"")} | G7: {=IFERROR(PERCENTILE(IF(Tijdlijn!$G$3:$G$17546=$A7*100+G$4,Tijdlijn!$E$3:$E$17546),Instellingen!$B$4),"")} | H7: {=IFERROR(PERCENTILE(IF(Tijdlijn!$G$3:$G$17546=$A7*100+H$4,Tijdlijn!$E$3:$E$17546),Instellingen!$B$4),"")} | I7: {=IFERROR(PERCENTILE(IF(Tijdlijn!$G$3:$G$17546=$A7*100+I$4,Tijdlijn!$E$3:$E$17546),Instellingen!$B$4),"")} | J7: {=IFERROR(PERCENTILE(IF(Tijdlijn!$G$3:$G$17546=$A7*100+J$4,Tijdlijn!$E$3:$E$17546),Instellingen!$B$4),"")} | ... Z7: {=IFERROR(PERCENTILE(IF(Tijdlijn!$G$3:$G$17546=$A7*100+Z$4,Tijdlijn!$E$3:$E$17546),Instellingen!$B$4),"")} | AA7: {=IFERROR(PERCENTILE(IF(Tijdlijn!$H$3:$H$17546=$A7,Tijdlijn!$E$3:$E$17546),Instellingen!$B$4),"")}
A8: 4 | B8: donderdag | C8: {=IFERROR(PERCENTILE(IF(Tijdlijn!$G$3:$G$17546=$A8*100+C$4,Tijdlijn!$E$3:$E$17546),Instellingen!$B$4),"")} | D8: {=IFERROR(PERCENTILE(IF(Tijdlijn!$G$3:$G$17546=$A8*100+D$4,Tijdlijn!$E$3:$E$17546),Instellingen!$B$4),"")} | E8: {=IFERROR(PERCENTILE(IF(Tijdlijn!$G$3:$G$17546=$A8*100+E$4,Tijdlijn!$E$3:$E$17546),Instellingen!$B$4),"")} | F8: {=IFERROR(PERCENTILE(IF(Tijdlijn!$G$3:$G$17546=$A8*100+F$4,Tijdlijn!$E$3:$E$17546),Instellingen!$B$4),"")} | G8: {=IFERROR(PERCENTILE(IF(Tijdlijn!$G$3:$G$17546=$A8*100+G$4,Tijdlijn!$E$3:$E$17546),Instellingen!$B$4),"")} | H8: {=IFERROR(PERCENTILE(IF(Tijdlijn!$G$3:$G$17546=$A8*100+H$4,Tijdlijn!$E$3:$E$17546),Instellingen!$B$4),"")} | I8: {=IFERROR(PERCENTILE(IF(Tijdlijn!$G$3:$G$17546=$A8*100+I$4,Tijdlijn!$E$3:$E$17546),Instellingen!$B$4),"")} | J8: {=IFERROR(PERCENTILE(IF(Tijdlijn!$G$3:$G$17546=$A8*100+J$4,Tijdlijn!$E$3:$E$17546),Instellingen!$B$4),"")} | ... Z8: {=IFERROR(PERCENTILE(IF(Tijdlijn!$G$3:$G$17546=$A8*100+Z$4,Tijdlijn!$E$3:$E$17546),Instellingen!$B$4),"")} | AA8: {=IFERROR(PERCENTILE(IF(Tijdlijn!$H$3:$H$17546=$A8,Tijdlijn!$E$3:$E$17546),Instellingen!$B$4),"")}
A9: 5 | B9: vrijdag | C9: {=IFERROR(PERCENTILE(IF(Tijdlijn!$G$3:$G$17546=$A9*100+C$4,Tijdlijn!$E$3:$E$17546),Instellingen!$B$4),"")} | D9: {=IFERROR(PERCENTILE(IF(Tijdlijn!$G$3:$G$17546=$A9*100+D$4,Tijdlijn!$E$3:$E$17546),Instellingen!$B$4),"")} | E9: {=IFERROR(PERCENTILE(IF(Tijdlijn!$G$3:$G$17546=$A9*100+E$4,Tijdlijn!$E$3:$E$17546),Instellingen!$B$4),"")} | F9: {=IFERROR(PERCENTILE(IF(Tijdlijn!$G$3:$G$17546=$A9*100+F$4,Tijdlijn!$E$3:$E$17546),Instellingen!$B$4),"")} | G9: {=IFERROR(PERCENTILE(IF(Tijdlijn!$G$3:$G$17546=$A9*100+G$4,Tijdlijn!$E$3:$E$17546),Instellingen!$B$4),"")} | H9: {=IFERROR(PERCENTILE(IF(Tijdlijn!$G$3:$G$17546=$A9*100+H$4,Tijdlijn!$E$3:$E$17546),Instellingen!$B$4),"")} | I9: {=IFERROR(PERCENTILE(IF(Tijdlijn!$G$3:$G$17546=$A9*100+I$4,Tijdlijn!$E$3:$E$17546),Instellingen!$B$4),"")} | J9: {=IFERROR(PERCENTILE(IF(Tijdlijn!$G$3:$G$17546=$A9*100+J$4,Tijdlijn!$E$3:$E$17546),Instellingen!$B$4),"")} | ... Z9: {=IFERROR(PERCENTILE(IF(Tijdlijn!$G$3:$G$17546=$A9*100+Z$4,Tijdlijn!$E$3:$E$17546),Instellingen!$B$4),"")} | AA9: {=IFERROR(PERCENTILE(IF(Tijdlijn!$H$3:$H$17546=$A9,Tijdlijn!$E$3:$E$17546),Instellingen!$B$4),"")}
A10: 6 | B10: zaterdag | C10: {=IFERROR(PERCENTILE(IF(Tijdlijn!$G$3:$G$17546=$A10*100+C$4,Tijdlijn!$E$3:$E$17546),Instellingen!$B$4),"")} | D10: {=IFERROR(PERCENTILE(IF(Tijdlijn!$G$3:$G$17546=$A10*100+D$4,Tijdlijn!$E$3:$E$17546),Instellingen!$B$4),"")} | E10: {=IFERROR(PERCENTILE(IF(Tijdlijn!$G$3:$G$17546=$A10*100+E$4,Tijdlijn!$E$3:$E$17546),Instellingen!$B$4),"")} | F10: {=IFERROR(PERCENTILE(IF(Tijdlijn!$G$3:$G$17546=$A10*100+F$4,Tijdlijn!$E$3:$E$17546),Instellingen!$B$4),"")} | G10: {=IFERROR(PERCENTILE(IF(Tijdlijn!$G$3:$G$17546=$A10*100+G$4,Tijdlijn!$E$3:$E$17546),Instellingen!$B$4),"")} | H10: {=IFERROR(PERCENTILE(IF(Tijdlijn!$G$3:$G$17546=$A10*100+H$4,Tijdlijn!$E$3:$E$17546),Instellingen!$B$4),"")} | I10: {=IFERROR(PERCENTILE(IF(Tijdlijn!$G$3:$G$17546=$A10*100+I$4,Tijdlijn!$E$3:$E$17546),Instellingen!$B$4),"")} | J10: {=IFERROR(PERCENTILE(IF(Tijdlijn!$G$3:$G$17546=$A10*100+J$4,Tijdlijn!$E$3:$E$17546),Instellingen!$B$4),"")} | ... Z10: {=IFERROR(PERCENTILE(IF(Tijdlijn!$G$3:$G$17546=$A10*100+Z$4,Tijdlijn!$E$3:$E$17546),Instellingen!$B$4),"")} | AA10: {=IFERROR(PERCENTILE(IF(Tijdlijn!$H$3:$H$17546=$A10,Tijdlijn!$E$3:$E$17546),Instellingen!$B$4),"")}
A11: 7 | B11: zondag | C11: {=IFERROR(PERCENTILE(IF(Tijdlijn!$G$3:$G$17546=$A11*100+C$4,Tijdlijn!$E$3:$E$17546),Instellingen!$B$4),"")} | D11: {=IFERROR(PERCENTILE(IF(Tijdlijn!$G$3:$G$17546=$A11*100+D$4,Tijdlijn!$E$3:$E$17546),Instellingen!$B$4),"")} | E11: {=IFERROR(PERCENTILE(IF(Tijdlijn!$G$3:$G$17546=$A11*100+E$4,Tijdlijn!$E$3:$E$17546),Instellingen!$B$4),"")} | F11: {=IFERROR(PERCENTILE(IF(Tijdlijn!$G$3:$G$17546=$A11*100+F$4,Tijdlijn!$E$3:$E$17546),Instellingen!$B$4),"")} | G11: {=IFERROR(PERCENTILE(IF(Tijdlijn!$G$3:$G$17546=$A11*100+G$4,Tijdlijn!$E$3:$E$17546),Instellingen!$B$4),"")} | H11: {=IFERROR(PERCENTILE(IF(Tijdlijn!$G$3:$G$17546=$A11*100+H$4,Tijdlijn!$E$3:$E$17546),Instellingen!$B$4),"")} | I11: {=IFERROR(PERCENTILE(IF(Tijdlijn!$G$3:$G$17546=$A11*100+I$4,Tijdlijn!$E$3:$E$17546),Instellingen!$B$4),"")} | J11: {=IFERROR(PERCENTILE(IF(Tijdlijn!$G$3:$G$17546=$A11*100+J$4,Tijdlijn!$E$3:$E$17546),Instellingen!$B$4),"")} | ... Z11: {=IFERROR(PERCENTILE(IF(Tijdlijn!$G$3:$G$17546=$A11*100+Z$4,Tijdlijn!$E$3:$E$17546),Instellingen!$B$4),"")} | AA11: {=IFERROR(PERCENTILE(IF(Tijdlijn!$H$3:$H$17546=$A11,Tijdlijn!$E$3:$E$17546),Instellingen!$B$4),"")}
B12: Alle dagen | C12: {=IFERROR(PERCENTILE(IF(Tijdlijn!$I$3:$I$17546=C$4,Tijdlijn!$E$3:$E$17546),Instellingen!$B$4),"")} | D12: {=IFERROR(PERCENTILE(IF(Tijdlijn!$I$3:$I$17546=D$4,Tijdlijn!$E$3:$E$17546),Instellingen!$B$4),"")} | E12: {=IFERROR(PERCENTILE(IF(Tijdlijn!$I$3:$I$17546=E$4,Tijdlijn!$E$3:$E$17546),Instellingen!$B$4),"")} | F12: {=IFERROR(PERCENTILE(IF(Tijdlijn!$I$3:$I$17546=F$4,Tijdlijn!$E$3:$E$17546),Instellingen!$B$4),"")} | G12: {=IFERROR(PERCENTILE(IF(Tijdlijn!$I$3:$I$17546=G$4,Tijdlijn!$E$3:$E$17546),Instellingen!$B$4),"")} | H12: {=IFERROR(PERCENTILE(IF(Tijdlijn!$I$3:$I$17546=H$4,Tijdlijn!$E$3:$E$17546),Instellingen!$B$4),"")} | I12: {=IFERROR(PERCENTILE(IF(Tijdlijn!$I$3:$I$17546=I$4,Tijdlijn!$E$3:$E$17546),Instellingen!$B$4),"")} | J12: {=IFERROR(PERCENTILE(IF(Tijdlijn!$I$3:$I$17546=J$4,Tijdlijn!$E$3:$E$17546),Instellingen!$B$4),"")} | ... Z12: {=IFERROR(PERCENTILE(IF(Tijdlijn!$I$3:$I$17546=Z$4,Tijdlijn!$E$3:$E$17546),Instellingen!$B$4),"")} | AA12: {=IFERROR(PERCENTILE(IF(Tijdlijn!$D$3:$D$17546=1,Tijdlijn!$E$3:$E$17546),Instellingen!$B$4),"")}
A15: Aandeel langliggers van het totaal (op drukke momenten)
A16: Van alle patiënten die er tegelijk liggen: welk deel is langligger? (P95-langliggers ÷ P95-totaal).
B18: Weekdag \ Uur | C18: 0 | D18: 1 | E18: 2 | F18: 3 | G18: 4 | H18: 5 | I18: 6 | J18: 7 | K18: 8 | L18: 9 | M18: 10 | N18: 11 | O18: 12 | P18: 13 | Q18: 14 | R18: 15 | S18: 16 | T18: 17 | U18: 18 | V18: 19 | W18: 20 | X18: 21 | Y18: 22 | Z18: 23 | AA18: Hele dag
B19: maandag | C19: =IFERROR('Q1_Verdeling'!C5/'Q2_Ratio'!C5,"") | D19: =IFERROR('Q1_Verdeling'!D5/'Q2_Ratio'!D5,"") | E19: =IFERROR('Q1_Verdeling'!E5/'Q2_Ratio'!E5,"") | F19: =IFERROR('Q1_Verdeling'!F5/'Q2_Ratio'!F5,"") | G19: =IFERROR('Q1_Verdeling'!G5/'Q2_Ratio'!G5,"") | H19: =IFERROR('Q1_Verdeling'!H5/'Q2_Ratio'!H5,"") | I19: =IFERROR('Q1_Verdeling'!I5/'Q2_Ratio'!I5,"") | J19: =IFERROR('Q1_Verdeling'!J5/'Q2_Ratio'!J5,"") | ... AA19: =IFERROR('Q1_Verdeling'!AA5/'Q2_Ratio'!AA5,"")
B20: dinsdag | C20: =IFERROR('Q1_Verdeling'!C6/'Q2_Ratio'!C6,"") | D20: =IFERROR('Q1_Verdeling'!D6/'Q2_Ratio'!D6,"") | E20: =IFERROR('Q1_Verdeling'!E6/'Q2_Ratio'!E6,"") | F20: =IFERROR('Q1_Verdeling'!F6/'Q2_Ratio'!F6,"") | G20: =IFERROR('Q1_Verdeling'!G6/'Q2_Ratio'!G6,"") | H20: =IFERROR('Q1_Verdeling'!H6/'Q2_Ratio'!H6,"") | I20: =IFERROR('Q1_Verdeling'!I6/'Q2_Ratio'!I6,"") | J20: =IFERROR('Q1_Verdeling'!J6/'Q2_Ratio'!J6,"") | ... AA20: =IFERROR('Q1_Verdeling'!AA6/'Q2_Ratio'!AA6,"")
B21: woensdag | C21: =IFERROR('Q1_Verdeling'!C7/'Q2_Ratio'!C7,"") | D21: =IFERROR('Q1_Verdeling'!D7/'Q2_Ratio'!D7,"") | E21: =IFERROR('Q1_Verdeling'!E7/'Q2_Ratio'!E7,"") | F21: =IFERROR('Q1_Verdeling'!F7/'Q2_Ratio'!F7,"") | G21: =IFERROR('Q1_Verdeling'!G7/'Q2_Ratio'!G7,"") | H21: =IFERROR('Q1_Verdeling'!H7/'Q2_Ratio'!H7,"") | I21: =IFERROR('Q1_Verdeling'!I7/'Q2_Ratio'!I7,"") | J21: =IFERROR('Q1_Verdeling'!J7/'Q2_Ratio'!J7,"") | ... AA21: =IFERROR('Q1_Verdeling'!AA7/'Q2_Ratio'!AA7,"")
B22: donderdag | C22: =IFERROR('Q1_Verdeling'!C8/'Q2_Ratio'!C8,"") | D22: =IFERROR('Q1_Verdeling'!D8/'Q2_Ratio'!D8,"") | E22: =IFERROR('Q1_Verdeling'!E8/'Q2_Ratio'!E8,"") | F22: =IFERROR('Q1_Verdeling'!F8/'Q2_Ratio'!F8,"") | G22: =IFERROR('Q1_Verdeling'!G8/'Q2_Ratio'!G8,"") | H22: =IFERROR('Q1_Verdeling'!H8/'Q2_Ratio'!H8,"") | I22: =IFERROR('Q1_Verdeling'!I8/'Q2_Ratio'!I8,"") | J22: =IFERROR('Q1_Verdeling'!J8/'Q2_Ratio'!J8,"") | ... AA22: =IFERROR('Q1_Verdeling'!AA8/'Q2_Ratio'!AA8,"")
B23: vrijdag | C23: =IFERROR('Q1_Verdeling'!C9/'Q2_Ratio'!C9,"") | D23: =IFERROR('Q1_Verdeling'!D9/'Q2_Ratio'!D9,"") | E23: =IFERROR('Q1_Verdeling'!E9/'Q2_Ratio'!E9,"") | F23: =IFERROR('Q1_Verdeling'!F9/'Q2_Ratio'!F9,"") | G23: =IFERROR('Q1_Verdeling'!G9/'Q2_Ratio'!G9,"") | H23: =IFERROR('Q1_Verdeling'!H9/'Q2_Ratio'!H9,"") | I23: =IFERROR('Q1_Verdeling'!I9/'Q2_Ratio'!I9,"") | J23: =IFERROR('Q1_Verdeling'!J9/'Q2_Ratio'!J9,"") | ... AA23: =IFERROR('Q1_Verdeling'!AA9/'Q2_Ratio'!AA9,"")
B24: zaterdag | C24: =IFERROR('Q1_Verdeling'!C10/'Q2_Ratio'!C10,"") | D24: =IFERROR('Q1_Verdeling'!D10/'Q2_Ratio'!D10,"") | E24: =IFERROR('Q1_Verdeling'!E10/'Q2_Ratio'!E10,"") | F24: =IFERROR('Q1_Verdeling'!F10/'Q2_Ratio'!F10,"") | G24: =IFERROR('Q1_Verdeling'!G10/'Q2_Ratio'!G10,"") | H24: =IFERROR('Q1_Verdeling'!H10/'Q2_Ratio'!H10,"") | I24: =IFERROR('Q1_Verdeling'!I10/'Q2_Ratio'!I10,"") | J24: =IFERROR('Q1_Verdeling'!J10/'Q2_Ratio'!J10,"") | ... AA24: =IFERROR('Q1_Verdeling'!AA10/'Q2_Ratio'!AA10,"")
B25: zondag | C25: =IFERROR('Q1_Verdeling'!C11/'Q2_Ratio'!C11,"") | D25: =IFERROR('Q1_Verdeling'!D11/'Q2_Ratio'!D11,"") | E25: =IFERROR('Q1_Verdeling'!E11/'Q2_Ratio'!E11,"") | F25: =IFERROR('Q1_Verdeling'!F11/'Q2_Ratio'!F11,"") | G25: =IFERROR('Q1_Verdeling'!G11/'Q2_Ratio'!G11,"") | H25: =IFERROR('Q1_Verdeling'!H11/'Q2_Ratio'!H11,"") | I25: =IFERROR('Q1_Verdeling'!I11/'Q2_Ratio'!I11,"") | J25: =IFERROR('Q1_Verdeling'!J11/'Q2_Ratio'!J11,"") | ... AA25: =IFERROR('Q1_Verdeling'!AA11/'Q2_Ratio'!AA11,"")
B26: Alle dagen | C26: =IFERROR('Q1_Verdeling'!C12/'Q2_Ratio'!C12,"") | D26: =IFERROR('Q1_Verdeling'!D12/'Q2_Ratio'!D12,"") | E26: =IFERROR('Q1_Verdeling'!E12/'Q2_Ratio'!E12,"") | F26: =IFERROR('Q1_Verdeling'!F12/'Q2_Ratio'!F12,"") | G26: =IFERROR('Q1_Verdeling'!G12/'Q2_Ratio'!G12,"") | H26: =IFERROR('Q1_Verdeling'!H12/'Q2_Ratio'!H12,"") | I26: =IFERROR('Q1_Verdeling'!I12/'Q2_Ratio'!I12,"") | J26: =IFERROR('Q1_Verdeling'!J12/'Q2_Ratio'!J12,"") | ... AA26: =IFERROR('Q1_Verdeling'!AA12/'Q2_Ratio'!AA12,"")

Sheet Q3_SEH-arts
A1: Vraag 3 – Per SEH-arts en per specialisme
A2: Vul (geel) de namen in zoals ze in kolom 'SEH specialist' staan; de kengetallen verschijnen vanzelf. Kolom 'Specialisme' wordt automatisch opgezocht. Wil je alleen de SEH-artsen? Filter in de onderste tabel op specialisme 'SEH'. Tip: een draaitabel op 'Data' geeft de volledige lijst.
A4: SEH-arts (invullen) | B4: Specialisme | C4: Aantal trajecten | D4: Aantal langliggers | E4: % langliggers | F4: Ligduur P95 (min) | G4: Ligduur P95 langlig. (min)
A5: Dr. Jansen | B5: =IF($A5="","",IFERROR(INDEX(tData[SpecialismeCodeIntern],MATCH($A5,tData[SEH specialist],0)),"")) | C5: =IF($A5="","",COUNTIF(tData[SEH specialist],$A5)) | D5: =IF($A5="","",COUNTIFS(tData[SEH specialist],$A5,tData[Duur_min],">"&Instellingen!$B$3)) | E5: =IF(OR($A5="",C5=0),"",D5/C5) | F5: {=IF($A5="","",IFERROR(PERCENTILE(IF(tData[SEH specialist]=$A5,tData[Duur_min]),Instellingen!$B$4),""))} | G5: {=IF($A5="","",IFERROR(PERCENTILE(IF((tData[SEH specialist]=$A5)*(tData[Duur_min]>Instellingen!$B$3),tData[Duur_min]),Instellingen!$B$4),""))}
B6: =IF($A6="","",IFERROR(INDEX(tData[SpecialismeCodeIntern],MATCH($A6,tData[SEH specialist],0)),"")) | C6: =IF($A6="","",COUNTIF(tData[SEH specialist],$A6)) | D6: =IF($A6="","",COUNTIFS(tData[SEH specialist],$A6,tData[Duur_min],">"&Instellingen!$B$3)) | E6: =IF(OR($A6="",C6=0),"",D6/C6) | F6: {=IF($A6="","",IFERROR(PERCENTILE(IF(tData[SEH specialist]=$A6,tData[Duur_min]),Instellingen!$B$4),""))} | G6: {=IF($A6="","",IFERROR(PERCENTILE(IF((tData[SEH specialist]=$A6)*(tData[Duur_min]>Instellingen!$B$3),tData[Duur_min]),Instellingen!$B$4),""))}
B7: =IF($A7="","",IFERROR(INDEX(tData[SpecialismeCodeIntern],MATCH($A7,tData[SEH specialist],0)),"")) | C7: =IF($A7="","",COUNTIF(tData[SEH specialist],$A7)) | D7: =IF($A7="","",COUNTIFS(tData[SEH specialist],$A7,tData[Duur_min],">"&Instellingen!$B$3)) | E7: =IF(OR($A7="",C7=0),"",D7/C7) | F7: {=IF($A7="","",IFERROR(PERCENTILE(IF(tData[SEH specialist]=$A7,tData[Duur_min]),Instellingen!$B$4),""))} | G7: {=IF($A7="","",IFERROR(PERCENTILE(IF((tData[SEH specialist]=$A7)*(tData[Duur_min]>Instellingen!$B$3),tData[Duur_min]),Instellingen!$B$4),""))}
B8: =IF($A8="","",IFERROR(INDEX(tData[SpecialismeCodeIntern],MATCH($A8,tData[SEH specialist],0)),"")) | C8: =IF($A8="","",COUNTIF(tData[SEH specialist],$A8)) | D8: =IF($A8="","",COUNTIFS(tData[SEH specialist],$A8,tData[Duur_min],">"&Instellingen!$B$3)) | E8: =IF(OR($A8="",C8=0),"",D8/C8) | F8: {=IF($A8="","",IFERROR(PERCENTILE(IF(tData[SEH specialist]=$A8,tData[Duur_min]),Instellingen!$B$4),""))} | G8: {=IF($A8="","",IFERROR(PERCENTILE(IF((tData[SEH specialist]=$A8)*(tData[Duur_min]>Instellingen!$B$3),tData[Duur_min]),Instellingen!$B$4),""))}
B9: =IF($A9="","",IFERROR(INDEX(tData[SpecialismeCodeIntern],MATCH($A9,tData[SEH specialist],0)),"")) | C9: =IF($A9="","",COUNTIF(tData[SEH specialist],$A9)) | D9: =IF($A9="","",COUNTIFS(tData[SEH specialist],$A9,tData[Duur_min],">"&Instellingen!$B$3)) | E9: =IF(OR($A9="",C9=0),"",D9/C9) | F9: {=IF($A9="","",IFERROR(PERCENTILE(IF(tData[SEH specialist]=$A9,tData[Duur_min]),Instellingen!$B$4),""))} | G9: {=IF($A9="","",IFERROR(PERCENTILE(IF((tData[SEH specialist]=$A9)*(tData[Duur_min]>Instellingen!$B$3),tData[Duur_min]),Instellingen!$B$4),""))}
B10: =IF($A10="","",IFERROR(INDEX(tData[SpecialismeCodeIntern],MATCH($A10,tData[SEH specialist],0)),"")) | C10: =IF($A10="","",COUNTIF(tData[SEH specialist],$A10)) | D10: =IF($A10="","",COUNTIFS(tData[SEH specialist],$A10,tData[Duur_min],">"&Instellingen!$B$3)) | E10: =IF(OR($A10="",C10=0),"",D10/C10) | F10: {=IF($A10="","",IFERROR(PERCENTILE(IF(tData[SEH specialist]=$A10,tData[Duur_min]),Instellingen!$B$4),""))} | G10: {=IF($A10="","",IFERROR(PERCENTILE(IF((tData[SEH specialist]=$A10)*(tData[Duur_min]>Instellingen!$B$3),tData[Duur_min]),Instellingen!$B$4),""))}
B11: =IF($A11="","",IFERROR(INDEX(tData[SpecialismeCodeIntern],MATCH($A11,tData[SEH specialist],0)),"")) | C11: =IF($A11="","",COUNTIF(tData[SEH specialist],$A11)) | D11: =IF($A11="","",COUNTIFS(tData[SEH specialist],$A11,tData[Duur_min],">"&Instellingen!$B$3)) | E11: =IF(OR($A11="",C11=0),"",D11/C11) | F11: {=IF($A11="","",IFERROR(PERCENTILE(IF(tData[SEH specialist]=$A11,tData[Duur_min]),Instellingen!$B$4),""))} | G11: {=IF($A11="","",IFERROR(PERCENTILE(IF((tData[SEH specialist]=$A11)*(tData[Duur_min]>Instellingen!$B$3),tData[Duur_min]),Instellingen!$B$4),""))}
B12: =IF($A12="","",IFERROR(INDEX(tData[SpecialismeCodeIntern],MATCH($A12,tData[SEH specialist],0)),"")) | C12: =IF($A12="","",COUNTIF(tData[SEH specialist],$A12)) | D12: =IF($A12="","",COUNTIFS(tData[SEH specialist],$A12,tData[Duur_min],">"&Instellingen!$B$3)) | E12: =IF(OR($A12="",C12=0),"",D12/C12) | F12: {=IF($A12="","",IFERROR(PERCENTILE(IF(tData[SEH specialist]=$A12,tData[Duur_min]),Instellingen!$B$4),""))} | G12: {=IF($A12="","",IFERROR(PERCENTILE(IF((tData[SEH specialist]=$A12)*(tData[Duur_min]>Instellingen!$B$3),tData[Duur_min]),Instellingen!$B$4),""))}
B13: =IF($A13="","",IFERROR(INDEX(tData[SpecialismeCodeIntern],MATCH($A13,tData[SEH specialist],0)),"")) | C13: =IF($A13="","",COUNTIF(tData[SEH specialist],$A13)) | D13: =IF($A13="","",COUNTIFS(tData[SEH specialist],$A13,tData[Duur_min],">"&Instellingen!$B$3)) | E13: =IF(OR($A13="",C13=0),"",D13/C13) | F13: {=IF($A13="","",IFERROR(PERCENTILE(IF(tData[SEH specialist]=$A13,tData[Duur_min]),Instellingen!$B$4),""))} | G13: {=IF($A13="","",IFERROR(PERCENTILE(IF((tData[SEH specialist]=$A13)*(tData[Duur_min]>Instellingen!$B$3),tData[Duur_min]),Instellingen!$B$4),""))}
B14: =IF($A14="","",IFERROR(INDEX(tData[SpecialismeCodeIntern],MATCH($A14,tData[SEH specialist],0)),"")) | C14: =IF($A14="","",COUNTIF(tData[SEH specialist],$A14)) | D14: =IF($A14="","",COUNTIFS(tData[SEH specialist],$A14,tData[Duur_min],">"&Instellingen!$B$3)) | E14: =IF(OR($A14="",C14=0),"",D14/C14) | F14: {=IF($A14="","",IFERROR(PERCENTILE(IF(tData[SEH specialist]=$A14,tData[Duur_min]),Instellingen!$B$4),""))} | G14: {=IF($A14="","",IFERROR(PERCENTILE(IF((tData[SEH specialist]=$A14)*(tData[Duur_min]>Instellingen!$B$3),tData[Duur_min]),Instellingen!$B$4),""))}
B15: =IF($A15="","",IFERROR(INDEX(tData[SpecialismeCodeIntern],MATCH($A15,tData[SEH specialist],0)),"")) | C15: =IF($A15="","",COUNTIF(tData[SEH specialist],$A15)) | D15: =IF($A15="","",COUNTIFS(tData[SEH specialist],$A15,tData[Duur_min],">"&Instellingen!$B$3)) | E15: =IF(OR($A15="",C15=0),"",D15/C15) | F15: {=IF($A15="","",IFERROR(PERCENTILE(IF(tData[SEH specialist]=$A15,tData[Duur_min]),Instellingen!$B$4),""))} | G15: {=IF($A15="","",IFERROR(PERCENTILE(IF((tData[SEH specialist]=$A15)*(tData[Duur_min]>Instellingen!$B$3),tData[Duur_min]),Instellingen!$B$4),""))}
B16: =IF($A16="","",IFERROR(INDEX(tData[SpecialismeCodeIntern],MATCH($A16,tData[SEH specialist],0)),"")) | C16: =IF($A16="","",COUNTIF(tData[SEH specialist],$A16)) | D16: =IF($A16="","",COUNTIFS(tData[SEH specialist],$A16,tData[Duur_min],">"&Instellingen!$B$3)) | E16: =IF(OR($A16="",C16=0),"",D16/C16) | F16: {=IF($A16="","",IFERROR(PERCENTILE(IF(tData[SEH specialist]=$A16,tData[Duur_min]),Instellingen!$B$4),""))} | G16: {=IF($A16="","",IFERROR(PERCENTILE(IF((tData[SEH specialist]=$A16)*(tData[Duur_min]>Instellingen!$B$3),tData[Duur_min]),Instellingen!$B$4),""))}
A19: Per specialisme (SpecialismeCodeIntern)
A20: Specialisme (invullen) | B20: Aantal trajecten | C20: Aantal langliggers | D20: % langliggers | E20: Ligduur P95 (min) | F20: Ligduur P95 langlig. (min)
A21: SEH | B21: =IF($A21="","",COUNTIF(tData[SpecialismeCodeIntern],$A21)) | C21: =IF($A21="","",COUNTIFS(tData[SpecialismeCodeIntern],$A21,tData[Duur_min],">"&Instellingen!$B$3)) | D21: =IF(OR($A21="",B21=0),"",C21/B21) | E21: {=IF($A21="","",IFERROR(PERCENTILE(IF(tData[SpecialismeCodeIntern]=$A21,tData[Duur_min]),Instellingen!$B$4),""))} | F21: {=IF($A21="","",IFERROR(PERCENTILE(IF((tData[SpecialismeCodeIntern]=$A21)*(tData[Duur_min]>Instellingen!$B$3),tData[Duur_min]),Instellingen!$B$4),""))}
A22: MDL | B22: =IF($A22="","",COUNTIF(tData[SpecialismeCodeIntern],$A22)) | C22: =IF($A22="","",COUNTIFS(tData[SpecialismeCodeIntern],$A22,tData[Duur_min],">"&Instellingen!$B$3)) | D22: =IF(OR($A22="",B22=0),"",C22/B22) | E22: {=IF($A22="","",IFERROR(PERCENTILE(IF(tData[SpecialismeCodeIntern]=$A22,tData[Duur_min]),Instellingen!$B$4),""))} | F22: {=IF($A22="","",IFERROR(PERCENTILE(IF((tData[SpecialismeCodeIntern]=$A22)*(tData[Duur_min]>Instellingen!$B$3),tData[Duur_min]),Instellingen!$B$4),""))}
A23: LONG | B23: =IF($A23="","",COUNTIF(tData[SpecialismeCodeIntern],$A23)) | C23: =IF($A23="","",COUNTIFS(tData[SpecialismeCodeIntern],$A23,tData[Duur_min],">"&Instellingen!$B$3)) | D23: =IF(OR($A23="",B23=0),"",C23/B23) | E23: {=IF($A23="","",IFERROR(PERCENTILE(IF(tData[SpecialismeCodeIntern]=$A23,tData[Duur_min]),Instellingen!$B$4),""))} | F23: {=IF($A23="","",IFERROR(PERCENTILE(IF((tData[SpecialismeCodeIntern]=$A23)*(tData[Duur_min]>Instellingen!$B$3),tData[Duur_min]),Instellingen!$B$4),""))}
A24: CARD | B24: =IF($A24="","",COUNTIF(tData[SpecialismeCodeIntern],$A24)) | C24: =IF($A24="","",COUNTIFS(tData[SpecialismeCodeIntern],$A24,tData[Duur_min],">"&Instellingen!$B$3)) | D24: =IF(OR($A24="",B24=0),"",C24/B24) | E24: {=IF($A24="","",IFERROR(PERCENTILE(IF(tData[SpecialismeCodeIntern]=$A24,tData[Duur_min]),Instellingen!$B$4),""))} | F24: {=IF($A24="","",IFERROR(PERCENTILE(IF((tData[SpecialismeCodeIntern]=$A24)*(tData[Duur_min]>Instellingen!$B$3),tData[Duur_min]),Instellingen!$B$4),""))}
A25: CHIR | B25: =IF($A25="","",COUNTIF(tData[SpecialismeCodeIntern],$A25)) | C25: =IF($A25="","",COUNTIFS(tData[SpecialismeCodeIntern],$A25,tData[Duur_min],">"&Instellingen!$B$3)) | D25: =IF(OR($A25="",B25=0),"",C25/B25) | E25: {=IF($A25="","",IFERROR(PERCENTILE(IF(tData[SpecialismeCodeIntern]=$A25,tData[Duur_min]),Instellingen!$B$4),""))} | F25: {=IF($A25="","",IFERROR(PERCENTILE(IF((tData[SpecialismeCodeIntern]=$A25)*(tData[Duur_min]>Instellingen!$B$3),tData[Duur_min]),Instellingen!$B$4),""))}
A26: INT | B26: =IF($A26="","",COUNTIF(tData[SpecialismeCodeIntern],$A26)) | C26: =IF($A26="","",COUNTIFS(tData[SpecialismeCodeIntern],$A26,tData[Duur_min],">"&Instellingen!$B$3)) | D26: =IF(OR($A26="",B26=0),"",C26/B26) | E26: {=IF($A26="","",IFERROR(PERCENTILE(IF(tData[SpecialismeCodeIntern]=$A26,tData[Duur_min]),Instellingen!$B$4),""))} | F26: {=IF($A26="","",IFERROR(PERCENTILE(IF((tData[SpecialismeCodeIntern]=$A26)*(tData[Duur_min]>Instellingen!$B$3),tData[Duur_min]),Instellingen!$B$4),""))}
A27: NEU | B27: =IF($A27="","",COUNTIF(tData[SpecialismeCodeIntern],$A27)) | C27: =IF($A27="","",COUNTIFS(tData[SpecialismeCodeIntern],$A27,tData[Duur_min],">"&Instellingen!$B$3)) | D27: =IF(OR($A27="",B27=0),"",C27/B27) | E27: {=IF($A27="","",IFERROR(PERCENTILE(IF(tData[SpecialismeCodeIntern]=$A27,tData[Duur_min]),Instellingen!$B$4),""))} | F27: {=IF($A27="","",IFERROR(PERCENTILE(IF((tData[SpecialismeCodeIntern]=$A27)*(tData[Duur_min]>Instellingen!$B$3),tData[Duur_min]),Instellingen!$B$4),""))}
A28: URO | B28: =IF($A28="","",COUNTIF(tData[SpecialismeCodeIntern],$A28)) | C28: =IF($A28="","",COUNTIFS(tData[SpecialismeCodeIntern],$A28,tData[Duur_min],">"&Instellingen!$B$3)) | D28: =IF(OR($A28="",B28=0),"",C28/B28) | E28: {=IF($A28="","",IFERROR(PERCENTILE(IF(tData[SpecialismeCodeIntern]=$A28,tData[Duur_min]),Instellingen!$B$4),""))} | F28: {=IF($A28="","",IFERROR(PERCENTILE(IF((tData[SpecialismeCodeIntern]=$A28)*(tData[Duur_min]>Instellingen!$B$3),tData[Duur_min]),Instellingen!$B$4),""))}
A29: ORT | B29: =IF($A29="","",COUNTIF(tData[SpecialismeCodeIntern],$A29)) | C29: =IF($A29="","",COUNTIFS(tData[SpecialismeCodeIntern],$A29,tData[Duur_min],">"&Instellingen!$B$3)) | D29: =IF(OR($A29="",B29=0),"",C29/B29) | E29: {=IF($A29="","",IFERROR(PERCENTILE(IF(tData[SpecialismeCodeIntern]=$A29,tData[Duur_min]),Instellingen!$B$4),""))} | F29: {=IF($A29="","",IFERROR(PERCENTILE(IF((tData[SpecialismeCodeIntern]=$A29)*(tData[Duur_min]>Instellingen!$B$3),tData[Duur_min]),Instellingen!$B$4),""))}
A30: KNO | B30: =IF($A30="","",COUNTIF(tData[SpecialismeCodeIntern],$A30)) | C30: =IF($A30="","",COUNTIFS(tData[SpecialismeCodeIntern],$A30,tData[Duur_min],">"&Instellingen!$B$3)) | D30: =IF(OR($A30="",B30=0),"",C30/B30) | E30: {=IF($A30="","",IFERROR(PERCENTILE(IF(tData[SpecialismeCodeIntern]=$A30,tData[Duur_min]),Instellingen!$B$4),""))} | F30: {=IF($A30="","",IFERROR(PERCENTILE(IF((tData[SpecialismeCodeIntern]=$A30)*(tData[Duur_min]>Instellingen!$B$3),tData[Duur_min]),Instellingen!$B$4),""))}
A31: GYN | B31: =IF($A31="","",COUNTIF(tData[SpecialismeCodeIntern],$A31)) | C31: =IF($A31="","",COUNTIFS(tData[SpecialismeCodeIntern],$A31,tData[Duur_min],">"&Instellingen!$B$3)) | D31: =IF(OR($A31="",B31=0),"",C31/B31) | E31: {=IF($A31="","",IFERROR(PERCENTILE(IF(tData[SpecialismeCodeIntern]=$A31,tData[Duur_min]),Instellingen!$B$4),""))} | F31: {=IF($A31="","",IFERROR(PERCENTILE(IF((tData[SpecialismeCodeIntern]=$A31)*(tData[Duur_min]>Instellingen!$B$3),tData[Duur_min]),Instellingen!$B$4),""))}
A32: KIND | B32: =IF($A32="","",COUNTIF(tData[SpecialismeCodeIntern],$A32)) | C32: =IF($A32="","",COUNTIFS(tData[SpecialismeCodeIntern],$A32,tData[Duur_min],">"&Instellingen!$B$3)) | D32: =IF(OR($A32="",B32=0),"",C32/B32) | E32: {=IF($A32="","",IFERROR(PERCENTILE(IF(tData[SpecialismeCodeIntern]=$A32,tData[Duur_min]),Instellingen!$B$4),""))} | F32: {=IF($A32="","",IFERROR(PERCENTILE(IF((tData[SpecialismeCodeIntern]=$A32)*(tData[Duur_min]>Instellingen!$B$3),tData[Duur_min]),Instellingen!$B$4),""))}
A34: Belangrijk – SEH-arts als medebehandelaar
A35: Filter op specialisme 'SEH' om alleen de door SEH-artsen behandelde perioden te zien. Let op: na ontslag van de SEH wordt soms een poortspecialist hoofdbehandelaar (bv. MDL/LONG) terwijl de SEH-arts MEDEbehandelaar blijft. Toont de export dan alleen de poortspecialist, dan is de SEH-arts als medebehandelaar niet zichtbaar. Voor 100% zekerheid: vraag in de bron een aparte kolom 'Regievoerend SEH-arts' / 'SEH-arts (mede)behandelaar' mee, zet die hier bij en filter daarop.

Sheet Instellingen
A1: Instellingen
A3: Drempel langligger (minuten) | B3: 240 | C3: Invoer. 240 min = 4 uur. Pas aan om bv. > 3 uur te bekijken.
A4: Percentiel (0,95 = 95e percentiel) | B4: 0.95 | C4: Invoer. 0,95 = de drukke momenten (95% van de tijd is het niet drukker dan dit). 0,50 zou de mediaan zijn.
A6: Begin data-periode (automatisch) | B6: =IFERROR(MIN(tData[Start]),"") | C6: Vroegste Start in je data.
A7: Einde data-periode (automatisch) | B7: =IFERROR(MAX(tData[Eind]),"") | C7: Laatste Eind in je data.
A9: Aantal SEH-bezoeken (patiënten) | B9: =COUNTIF(tData[EersteRegelBezoek],1) | C9: Elk SEH-bezoek (periode-ID) telt 1×, ook bij kamerwissels. Dit is de basis voor de bezetting.
A10: Aantal langligger-bezoeken | B10: =COUNTIF(tData[BezoekLanglig],1) | C10: Bezoeken met totale ligduur (max Eind – min Start) boven de drempel.
A11: Aantal regels (perioden) | B11: =COUNT(tData[Start]) | C11: Aantal geplakte regels. Kan hoger zijn dan het aantal bezoeken (kamerwissels).

Sheet Tijdlijn
A1: Tijdlijn = de bezetting per DATUM en UUR. 'Aanwezig_Totaal' en 'Aanwezig_Langlig' = aantal SEH-BEZOEKEN (patiënten) dat op dat uur tegelijk aanwezig is (kamerwissels tellen 1×). Hier kun je de bezetting controleren. De grafieken/Q1/Q2 nemen hiervan het 95e percentiel. KEY-kolommen niet wijzigen.
A2: Tijdstip | B2: Weekdag_num | C2: Uur | D2: InBereik | E2: Aanwezig_Totaal | F2: Aanwezig_Langlig | G2: KEY_wu | H2: KEY_wd | I2: KEY_uur
A3: 45292 | B3: =WEEKDAY($A3,2) | C3: =HOUR($A3) | D3: =IF(AND($A3>=Instellingen!$B$6,$A3<Instellingen!$B$7),1,0) | E3: =COUNTIF(tData[BezoekStart],"<"&($A3+1/24))-COUNTIF(tData[BezoekEind],"<="&$A3) | F3: =COUNTIF(tData[BezoekLangStart],"<"&($A3+1/24))-COUNTIF(tData[BezoekLangEind],"<="&$A3) | G3: =IF($D3=1,$B3*100+$C3,-1) | H3: =IF($D3=1,$B3,-1) | I3: =IF($D3=1,$C3,-1)
A4: 45292.042 | B4: =WEEKDAY($A4,2) | C4: =HOUR($A4) | D4: =IF(AND($A4>=Instellingen!$B$6,$A4<Instellingen!$B$7),1,0) | E4: =COUNTIF(tData[BezoekStart],"<"&($A4+1/24))-COUNTIF(tData[BezoekEind],"<="&$A4) | F4: =COUNTIF(tData[BezoekLangStart],"<"&($A4+1/24))-COUNTIF(tData[BezoekLangEind],"<="&$A4) | G4: =IF($D4=1,$B4*100+$C4,-1) | H4: =IF($D4=1,$B4,-1) | I4: =IF($D4=1,$C4,-1)
A5: 45292.083 | B5: =WEEKDAY($A5,2) | C5: =HOUR($A5) | D5: =IF(AND($A5>=Instellingen!$B$6,$A5<Instellingen!$B$7),1,0) | E5: =COUNTIF(tData[BezoekStart],"<"&($A5+1/24))-COUNTIF(tData[BezoekEind],"<="&$A5) | F5: =COUNTIF(tData[BezoekLangStart],"<"&($A5+1/24))-COUNTIF(tData[BezoekLangEind],"<="&$A5) | G5: =IF($D5=1,$B5*100+$C5,-1) | H5: =IF($D5=1,$B5,-1) | I5: =IF($D5=1,$C5,-1)
A6: 45292.125 | B6: =WEEKDAY($A6,2) | C6: =HOUR($A6) | D6: =IF(AND($A6>=Instellingen!$B$6,$A6<Instellingen!$B$7),1,0) | E6: =COUNTIF(tData[BezoekStart],"<"&($A6+1/24))-COUNTIF(tData[BezoekEind],"<="&$A6) | F6: =COUNTIF(tData[BezoekLangStart],"<"&($A6+1/24))-COUNTIF(tData[BezoekLangEind],"<="&$A6) | G6: =IF($D6=1,$B6*100+$C6,-1) | H6: =IF($D6=1,$B6,-1) | I6: =IF($D6=1,$C6,-1)
A7: 45292.167 | B7: =WEEKDAY($A7,2) | C7: =HOUR($A7) | D7: =IF(AND($A7>=Instellingen!$B$6,$A7<Instellingen!$B$7),1,0) | E7: =COUNTIF(tData[BezoekStart],"<"&($A7+1/24))-COUNTIF(tData[BezoekEind],"<="&$A7) | F7: =COUNTIF(tData[BezoekLangStart],"<"&($A7+1/24))-COUNTIF(tData[BezoekLangEind],"<="&$A7) | G7: =IF($D7=1,$B7*100+$C7,-1) | H7: =IF($D7=1,$B7,-1) | I7: =IF($D7=1,$C7,-1)
A8: 45292.208 | B8: =WEEKDAY($A8,2) | C8: =HOUR($A8) | D8: =IF(AND($A8>=Instellingen!$B$6,$A8<Instellingen!$B$7),1,0) | E8: =COUNTIF(tData[BezoekStart],"<"&($A8+1/24))-COUNTIF(tData[BezoekEind],"<="&$A8) | F8: =COUNTIF(tData[BezoekLangStart],"<"&($A8+1/24))-COUNTIF(tData[BezoekLangEind],"<="&$A8) | G8: =IF($D8=1,$B8*100+$C8,-1) | H8: =IF($D8=1,$B8,-1) | I8: =IF($D8=1,$C8,-1)
A9: 45292.25 | B9: =WEEKDAY($A9,2) | C9: =HOUR($A9) | D9: =IF(AND($A9>=Instellingen!$B$6,$A9<Instellingen!$B$7),1,0) | E9: =COUNTIF(tData[BezoekStart],"<"&($A9+1/24))-COUNTIF(tData[BezoekEind],"<="&$A9) | F9: =COUNTIF(tData[BezoekLangStart],"<"&($A9+1/24))-COUNTIF(tData[BezoekLangEind],"<="&$A9) | G9: =IF($D9=1,$B9*100+$C9,-1) | H9: =IF($D9=1,$B9,-1) | I9: =IF($D9=1,$C9,-1)
A10: 45292.292 | B10: =WEEKDAY($A10,2) | C10: =HOUR($A10) | D10: =IF(AND($A10>=Instellingen!$B$6,$A10<Instellingen!$B$7),1,0) | E10: =COUNTIF(tData[BezoekStart],"<"&($A10+1/24))-COUNTIF(tData[BezoekEind],"<="&$A10) | F10: =COUNTIF(tData[BezoekLangStart],"<"&($A10+1/24))-COUNTIF(tData[BezoekLangEind],"<="&$A10) | G10: =IF($D10=1,$B10*100+$C10,-1) | H10: =IF($D10=1,$B10,-1) | I10: =IF($D10=1,$C10,-1)
A11: 45292.333 | B11: =WEEKDAY($A11,2) | C11: =HOUR($A11) | D11: =IF(AND($A11>=Instellingen!$B$6,$A11<Instellingen!$B$7),1,0) | E11: =COUNTIF(tData[BezoekStart],"<"&($A11+1/24))-COUNTIF(tData[BezoekEind],"<="&$A11) | F11: =COUNTIF(tData[BezoekLangStart],"<"&($A11+1/24))-COUNTIF(tData[BezoekLangEind],"<="&$A11) | G11: =IF($D11=1,$B11*100+$C11,-1) | H11: =IF($D11=1,$B11,-1) | I11: =IF($D11=1,$C11,-1)
A12: 45292.375 | B12: =WEEKDAY($A12,2) | C12: =HOUR($A12) | D12: =IF(AND($A12>=Instellingen!$B$6,$A12<Instellingen!$B$7),1,0) | E12: =COUNTIF(tData[BezoekStart],"<"&($A12+1/24))-COUNTIF(tData[BezoekEind],"<="&$A12) | F12: =COUNTIF(tData[BezoekLangStart],"<"&($A12+1/24))-COUNTIF(tData[BezoekLangEind],"<="&$A12) | G12: =IF($D12=1,$B12*100+$C12,-1) | H12: =IF($D12=1,$B12,-1) | I12: =IF($D12=1,$C12,-1)
A13: 45292.417 | B13: =WEEKDAY($A13,2) | C13: =HOUR($A13) | D13: =IF(AND($A13>=Instellingen!$B$6,$A13<Instellingen!$B$7),1,0) | E13: =COUNTIF(tData[BezoekStart],"<"&($A13+1/24))-COUNTIF(tData[BezoekEind],"<="&$A13) | F13: =COUNTIF(tData[BezoekLangStart],"<"&($A13+1/24))-COUNTIF(tData[BezoekLangEind],"<="&$A13) | G13: =IF($D13=1,$B13*100+$C13,-1) | H13: =IF($D13=1,$B13,-1) | I13: =IF($D13=1,$C13,-1)
A14: 45292.458 | B14: =WEEKDAY($A14,2) | C14: =HOUR($A14) | D14: =IF(AND($A14>=Instellingen!$B$6,$A14<Instellingen!$B$7),1,0) | E14: =COUNTIF(tData[BezoekStart],"<"&($A14+1/24))-COUNTIF(tData[BezoekEind],"<="&$A14) | F14: =COUNTIF(tData[BezoekLangStart],"<"&($A14+1/24))-COUNTIF(tData[BezoekLangEind],"<="&$A14) | G14: =IF($D14=1,$B14*100+$C14,-1) | H14: =IF($D14=1,$B14,-1) | I14: =IF($D14=1,$C14,-1)
... A17546: 46022.958 | B17546: =WEEKDAY($A17546,2) | C17546: =HOUR($A17546) | D17546: =IF(AND($A17546>=Instellingen!$B$6,$A17546<Instellingen!$B$7),1,0) | E17546: =COUNTIF(tData[BezoekStart],"<"&($A17546+1/24))-COUNTIF(tData[BezoekEind],"<="&$A17546) | F17546: =COUNTIF(tData[BezoekLangStart],"<"&($A17546+1/24))-COUNTIF(tData[BezoekLangEind],"<="&$A17546) | G17546: =IF($D17546=1,$B17546*100+$C17546,-1) | H17546: =IF($D17546=1,$B17546,-1) | I17546: =IF($D17546=1,$C17546,-1)

Sheet Grafiekdata
A1: Hulpgegevens voor de grafieken op tabblad 'Grafieken'. Dit blad mag verborgen blijven; je hoeft er niets aan te doen.
A2: Langliggers per uur (P95) — per dag | J2: Totaal aanwezig per uur (P95) — per dag
A3: Uur | B3: maandag | C3: dinsdag | D3: woensdag | E3: donderdag | F3: vrijdag | G3: zaterdag | H3: zondag | J3: Uur | K3: maandag | L3: dinsdag | M3: woensdag | N3: donderdag | O3: vrijdag | P3: zaterdag | Q3: zondag | S3: Uur | T3: Langliggers | U3: Overige patiënten | V3: Totaal aanwezig | W3: Aandeel langliggers
A4: 0 | B4: =IFERROR('Q1_Verdeling'!C5+0,0) | C4: =IFERROR('Q1_Verdeling'!C6+0,0) | D4: =IFERROR('Q1_Verdeling'!C7+0,0) | E4: =IFERROR('Q1_Verdeling'!C8+0,0) | F4: =IFERROR('Q1_Verdeling'!C9+0,0) | G4: =IFERROR('Q1_Verdeling'!C10+0,0) | H4: =IFERROR('Q1_Verdeling'!C11+0,0) | J4: 0 | K4: =IFERROR('Q2_Ratio'!C5+0,0) | L4: =IFERROR('Q2_Ratio'!C6+0,0) | M4: =IFERROR('Q2_Ratio'!C7+0,0) | N4: =IFERROR('Q2_Ratio'!C8+0,0) | O4: =IFERROR('Q2_Ratio'!C9+0,0) | P4: =IFERROR('Q2_Ratio'!C10+0,0) | Q4: =IFERROR('Q2_Ratio'!C11+0,0) | S4: 0 | T4: =IFERROR(INDEX('Q1_Verdeling'!$C$5:$Z$11,Grafieken!$AB$8,0+1)+0,0) | U4: =MAX($V4-$T4,0) | V4: =IFERROR(INDEX('Q2_Ratio'!$C$5:$Z$11,Grafieken!$AB$8,0+1)+0,0) | W4: =IFERROR($T4/$V4,0)
A5: 1 | B5: =IFERROR('Q1_Verdeling'!D5+0,0) | C5: =IFERROR('Q1_Verdeling'!D6+0,0) | D5: =IFERROR('Q1_Verdeling'!D7+0,0) | E5: =IFERROR('Q1_Verdeling'!D8+0,0) | F5: =IFERROR('Q1_Verdeling'!D9+0,0) | G5: =IFERROR('Q1_Verdeling'!D10+0,0) | H5: =IFERROR('Q1_Verdeling'!D11+0,0) | J5: 1 | K5: =IFERROR('Q2_Ratio'!D5+0,0) | L5: =IFERROR('Q2_Ratio'!D6+0,0) | M5: =IFERROR('Q2_Ratio'!D7+0,0) | N5: =IFERROR('Q2_Ratio'!D8+0,0) | O5: =IFERROR('Q2_Ratio'!D9+0,0) | P5: =IFERROR('Q2_Ratio'!D10+0,0) | Q5: =IFERROR('Q2_Ratio'!D11+0,0) | S5: 1 | T5: =IFERROR(INDEX('Q1_Verdeling'!$C$5:$Z$11,Grafieken!$AB$8,1+1)+0,0) | U5: =MAX($V5-$T5,0) | V5: =IFERROR(INDEX('Q2_Ratio'!$C$5:$Z$11,Grafieken!$AB$8,1+1)+0,0) | W5: =IFERROR($T5/$V5,0)
A6: 2 | B6: =IFERROR('Q1_Verdeling'!E5+0,0) | C6: =IFERROR('Q1_Verdeling'!E6+0,0) | D6: =IFERROR('Q1_Verdeling'!E7+0,0) | E6: =IFERROR('Q1_Verdeling'!E8+0,0) | F6: =IFERROR('Q1_Verdeling'!E9+0,0) | G6: =IFERROR('Q1_Verdeling'!E10+0,0) | H6: =IFERROR('Q1_Verdeling'!E11+0,0) | J6: 2 | K6: =IFERROR('Q2_Ratio'!E5+0,0) | L6: =IFERROR('Q2_Ratio'!E6+0,0) | M6: =IFERROR('Q2_Ratio'!E7+0,0) | N6: =IFERROR('Q2_Ratio'!E8+0,0) | O6: =IFERROR('Q2_Ratio'!E9+0,0) | P6: =IFERROR('Q2_Ratio'!E10+0,0) | Q6: =IFERROR('Q2_Ratio'!E11+0,0) | S6: 2 | T6: =IFERROR(INDEX('Q1_Verdeling'!$C$5:$Z$11,Grafieken!$AB$8,2+1)+0,0) | U6: =MAX($V6-$T6,0) | V6: =IFERROR(INDEX('Q2_Ratio'!$C$5:$Z$11,Grafieken!$AB$8,2+1)+0,0) | W6: =IFERROR($T6/$V6,0)
A7: 3 | B7: =IFERROR('Q1_Verdeling'!F5+0,0) | C7: =IFERROR('Q1_Verdeling'!F6+0,0) | D7: =IFERROR('Q1_Verdeling'!F7+0,0) | E7: =IFERROR('Q1_Verdeling'!F8+0,0) | F7: =IFERROR('Q1_Verdeling'!F9+0,0) | G7: =IFERROR('Q1_Verdeling'!F10+0,0) | H7: =IFERROR('Q1_Verdeling'!F11+0,0) | J7: 3 | K7: =IFERROR('Q2_Ratio'!F5+0,0) | L7: =IFERROR('Q2_Ratio'!F6+0,0) | M7: =IFERROR('Q2_Ratio'!F7+0,0) | N7: =IFERROR('Q2_Ratio'!F8+0,0) | O7: =IFERROR('Q2_Ratio'!F9+0,0) | P7: =IFERROR('Q2_Ratio'!F10+0,0) | Q7: =IFERROR('Q2_Ratio'!F11+0,0) | S7: 3 | T7: =IFERROR(INDEX('Q1_Verdeling'!$C$5:$Z$11,Grafieken!$AB$8,3+1)+0,0) | U7: =MAX($V7-$T7,0) | V7: =IFERROR(INDEX('Q2_Ratio'!$C$5:$Z$11,Grafieken!$AB$8,3+1)+0,0) | W7: =IFERROR($T7/$V7,0)
A8: 4 | B8: =IFERROR('Q1_Verdeling'!G5+0,0) | C8: =IFERROR('Q1_Verdeling'!G6+0,0) | D8: =IFERROR('Q1_Verdeling'!G7+0,0) | E8: =IFERROR('Q1_Verdeling'!G8+0,0) | F8: =IFERROR('Q1_Verdeling'!G9+0,0) | G8: =IFERROR('Q1_Verdeling'!G10+0,0) | H8: =IFERROR('Q1_Verdeling'!G11+0,0) | J8: 4 | K8: =IFERROR('Q2_Ratio'!G5+0,0) | L8: =IFERROR('Q2_Ratio'!G6+0,0) | M8: =IFERROR('Q2_Ratio'!G7+0,0) | N8: =IFERROR('Q2_Ratio'!G8+0,0) | O8: =IFERROR('Q2_Ratio'!G9+0,0) | P8: =IFERROR('Q2_Ratio'!G10+0,0) | Q8: =IFERROR('Q2_Ratio'!G11+0,0) | S8: 4 | T8: =IFERROR(INDEX('Q1_Verdeling'!$C$5:$Z$11,Grafieken!$AB$8,4+1)+0,0) | U8: =MAX($V8-$T8,0) | V8: =IFERROR(INDEX('Q2_Ratio'!$C$5:$Z$11,Grafieken!$AB$8,4+1)+0,0) | W8: =IFERROR($T8/$V8,0)
A9: 5 | B9: =IFERROR('Q1_Verdeling'!H5+0,0) | C9: =IFERROR('Q1_Verdeling'!H6+0,0) | D9: =IFERROR('Q1_Verdeling'!H7+0,0) | E9: =IFERROR('Q1_Verdeling'!H8+0,0) | F9: =IFERROR('Q1_Verdeling'!H9+0,0) | G9: =IFERROR('Q1_Verdeling'!H10+0,0) | H9: =IFERROR('Q1_Verdeling'!H11+0,0) | J9: 5 | K9: =IFERROR('Q2_Ratio'!H5+0,0) | L9: =IFERROR('Q2_Ratio'!H6+0,0) | M9: =IFERROR('Q2_Ratio'!H7+0,0) | N9: =IFERROR('Q2_Ratio'!H8+0,0) | O9: =IFERROR('Q2_Ratio'!H9+0,0) | P9: =IFERROR('Q2_Ratio'!H10+0,0) | Q9: =IFERROR('Q2_Ratio'!H11+0,0) | S9: 5 | T9: =IFERROR(INDEX('Q1_Verdeling'!$C$5:$Z$11,Grafieken!$AB$8,5+1)+0,0) | U9: =MAX($V9-$T9,0) | V9: =IFERROR(INDEX('Q2_Ratio'!$C$5:$Z$11,Grafieken!$AB$8,5+1)+0,0) | W9: =IFERROR($T9/$V9,0)
A10: 6 | B10: =IFERROR('Q1_Verdeling'!I5+0,0) | C10: =IFERROR('Q1_Verdeling'!I6+0,0) | D10: =IFERROR('Q1_Verdeling'!I7+0,0) | E10: =IFERROR('Q1_Verdeling'!I8+0,0) | F10: =IFERROR('Q1_Verdeling'!I9+0,0) | G10: =IFERROR('Q1_Verdeling'!I10+0,0) | H10: =IFERROR('Q1_Verdeling'!I11+0,0) | J10: 6 | K10: =IFERROR('Q2_Ratio'!I5+0,0) | L10: =IFERROR('Q2_Ratio'!I6+0,0) | M10: =IFERROR('Q2_Ratio'!I7+0,0) | N10: =IFERROR('Q2_Ratio'!I8+0,0) | O10: =IFERROR('Q2_Ratio'!I9+0,0) | P10: =IFERROR('Q2_Ratio'!I10+0,0) | Q10: =IFERROR('Q2_Ratio'!I11+0,0) | S10: 6 | T10: =IFERROR(INDEX('Q1_Verdeling'!$C$5:$Z$11,Grafieken!$AB$8,6+1)+0,0) | U10: =MAX($V10-$T10,0) | V10: =IFERROR(INDEX('Q2_Ratio'!$C$5:$Z$11,Grafieken!$AB$8,6+1)+0,0) | W10: =IFERROR($T10/$V10,0)
A11: 7 | B11: =IFERROR('Q1_Verdeling'!J5+0,0) | C11: =IFERROR('Q1_Verdeling'!J6+0,0) | D11: =IFERROR('Q1_Verdeling'!J7+0,0) | E11: =IFERROR('Q1_Verdeling'!J8+0,0) | F11: =IFERROR('Q1_Verdeling'!J9+0,0) | G11: =IFERROR('Q1_Verdeling'!J10+0,0) | H11: =IFERROR('Q1_Verdeling'!J11+0,0) | J11: 7 | K11: =IFERROR('Q2_Ratio'!J5+0,0) | L11: =IFERROR('Q2_Ratio'!J6+0,0) | M11: =IFERROR('Q2_Ratio'!J7+0,0) | N11: =IFERROR('Q2_Ratio'!J8+0,0) | O11: =IFERROR('Q2_Ratio'!J9+0,0) | P11: =IFERROR('Q2_Ratio'!J10+0,0) | Q11: =IFERROR('Q2_Ratio'!J11+0,0) | S11: 7 | T11: =IFERROR(INDEX('Q1_Verdeling'!$C$5:$Z$11,Grafieken!$AB$8,7+1)+0,0) | U11: =MAX($V11-$T11,0) | V11: =IFERROR(INDEX('Q2_Ratio'!$C$5:$Z$11,Grafieken!$AB$8,7+1)+0,0) | W11: =IFERROR($T11/$V11,0)
A12: 8 | B12: =IFERROR('Q1_Verdeling'!K5+0,0) | C12: =IFERROR('Q1_Verdeling'!K6+0,0) | D12: =IFERROR('Q1_Verdeling'!K7+0,0) | E12: =IFERROR('Q1_Verdeling'!K8+0,0) | F12: =IFERROR('Q1_Verdeling'!K9+0,0) | G12: =IFERROR('Q1_Verdeling'!K10+0,0) | H12: =IFERROR('Q1_Verdeling'!K11+0,0) | J12: 8 | K12: =IFERROR('Q2_Ratio'!K5+0,0) | L12: =IFERROR('Q2_Ratio'!K6+0,0) | M12: =IFERROR('Q2_Ratio'!K7+0,0) | N12: =IFERROR('Q2_Ratio'!K8+0,0) | O12: =IFERROR('Q2_Ratio'!K9+0,0) | P12: =IFERROR('Q2_Ratio'!K10+0,0) | Q12: =IFERROR('Q2_Ratio'!K11+0,0) | S12: 8 | T12: =IFERROR(INDEX('Q1_Verdeling'!$C$5:$Z$11,Grafieken!$AB$8,8+1)+0,0) | U12: =MAX($V12-$T12,0) | V12: =IFERROR(INDEX('Q2_Ratio'!$C$5:$Z$11,Grafieken!$AB$8,8+1)+0,0) | W12: =IFERROR($T12/$V12,0)
A13: 9 | B13: =IFERROR('Q1_Verdeling'!L5+0,0) | C13: =IFERROR('Q1_Verdeling'!L6+0,0) | D13: =IFERROR('Q1_Verdeling'!L7+0,0) | E13: =IFERROR('Q1_Verdeling'!L8+0,0) | F13: =IFERROR('Q1_Verdeling'!L9+0,0) | G13: =IFERROR('Q1_Verdeling'!L10+0,0) | H13: =IFERROR('Q1_Verdeling'!L11+0,0) | J13: 9 | K13: =IFERROR('Q2_Ratio'!L5+0,0) | L13: =IFERROR('Q2_Ratio'!L6+0,0) | M13: =IFERROR('Q2_Ratio'!L7+0,0) | N13: =IFERROR('Q2_Ratio'!L8+0,0) | O13: =IFERROR('Q2_Ratio'!L9+0,0) | P13: =IFERROR('Q2_Ratio'!L10+0,0) | Q13: =IFERROR('Q2_Ratio'!L11+0,0) | S13: 9 | T13: =IFERROR(INDEX('Q1_Verdeling'!$C$5:$Z$11,Grafieken!$AB$8,9+1)+0,0) | U13: =MAX($V13-$T13,0) | V13: =IFERROR(INDEX('Q2_Ratio'!$C$5:$Z$11,Grafieken!$AB$8,9+1)+0,0) | W13: =IFERROR($T13/$V13,0)
A14: 10 | B14: =IFERROR('Q1_Verdeling'!M5+0,0) | C14: =IFERROR('Q1_Verdeling'!M6+0,0) | D14: =IFERROR('Q1_Verdeling'!M7+0,0) | E14: =IFERROR('Q1_Verdeling'!M8+0,0) | F14: =IFERROR('Q1_Verdeling'!M9+0,0) | G14: =IFERROR('Q1_Verdeling'!M10+0,0) | H14: =IFERROR('Q1_Verdeling'!M11+0,0) | J14: 10 | K14: =IFERROR('Q2_Ratio'!M5+0,0) | L14: =IFERROR('Q2_Ratio'!M6+0,0) | M14: =IFERROR('Q2_Ratio'!M7+0,0) | N14: =IFERROR('Q2_Ratio'!M8+0,0) | O14: =IFERROR('Q2_Ratio'!M9+0,0) | P14: =IFERROR('Q2_Ratio'!M10+0,0) | Q14: =IFERROR('Q2_Ratio'!M11+0,0) | S14: 10 | T14: =IFERROR(INDEX('Q1_Verdeling'!$C$5:$Z$11,Grafieken!$AB$8,10+1)+0,0) | U14: =MAX($V14-$T14,0) | V14: =IFERROR(INDEX('Q2_Ratio'!$C$5:$Z$11,Grafieken!$AB$8,10+1)+0,0) | W14: =IFERROR($T14/$V14,0)
A15: 11 | B15: =IFERROR('Q1_Verdeling'!N5+0,0) | C15: =IFERROR('Q1_Verdeling'!N6+0,0) | D15: =IFERROR('Q1_Verdeling'!N7+0,0) | E15: =IFERROR('Q1_Verdeling'!N8+0,0) | F15: =IFERROR('Q1_Verdeling'!N9+0,0) | G15: =IFERROR('Q1_Verdeling'!N10+0,0) | H15: =IFERROR('Q1_Verdeling'!N11+0,0) | J15: 11 | K15: =IFERROR('Q2_Ratio'!N5+0,0) | L15: =IFERROR('Q2_Ratio'!N6+0,0) | M15: =IFERROR('Q2_Ratio'!N7+0,0) | N15: =IFERROR('Q2_Ratio'!N8+0,0) | O15: =IFERROR('Q2_Ratio'!N9+0,0) | P15: =IFERROR('Q2_Ratio'!N10+0,0) | Q15: =IFERROR('Q2_Ratio'!N11+0,0) | S15: 11 | T15: =IFERROR(INDEX('Q1_Verdeling'!$C$5:$Z$11,Grafieken!$AB$8,11+1)+0,0) | U15: =MAX($V15-$T15,0) | V15: =IFERROR(INDEX('Q2_Ratio'!$C$5:$Z$11,Grafieken!$AB$8,11+1)+0,0) | W15: =IFERROR($T15/$V15,0)
A16: 12 | B16: =IFERROR('Q1_Verdeling'!O5+0,0) | C16: =IFERROR('Q1_Verdeling'!O6+0,0) | D16: =IFERROR('Q1_Verdeling'!O7+0,0) | E16: =IFERROR('Q1_Verdeling'!O8+0,0) | F16: =IFERROR('Q1_Verdeling'!O9+0,0) | G16: =IFERROR('Q1_Verdeling'!O10+0,0) | H16: =IFERROR('Q1_Verdeling'!O11+0,0) | J16: 12 | K16: =IFERROR('Q2_Ratio'!O5+0,0) | L16: =IFERROR('Q2_Ratio'!O6+0,0) | M16: =IFERROR('Q2_Ratio'!O7+0,0) | N16: =IFERROR('Q2_Ratio'!O8+0,0) | O16: =IFERROR('Q2_Ratio'!O9+0,0) | P16: =IFERROR('Q2_Ratio'!O10+0,0) | Q16: =IFERROR('Q2_Ratio'!O11+0,0) | S16: 12 | T16: =IFERROR(INDEX('Q1_Verdeling'!$C$5:$Z$11,Grafieken!$AB$8,12+1)+0,0) | U16: =MAX($V16-$T16,0) | V16: =IFERROR(INDEX('Q2_Ratio'!$C$5:$Z$11,Grafieken!$AB$8,12+1)+0,0) | W16: =IFERROR($T16/$V16,0)
A17: 13 | B17: =IFERROR('Q1_Verdeling'!P5+0,0) | C17: =IFERROR('Q1_Verdeling'!P6+0,0) | D17: =IFERROR('Q1_Verdeling'!P7+0,0) | E17: =IFERROR('Q1_Verdeling'!P8+0,0) | F17: =IFERROR('Q1_Verdeling'!P9+0,0) | G17: =IFERROR('Q1_Verdeling'!P10+0,0) | H17: =IFERROR('Q1_Verdeling'!P11+0,0) | J17: 13 | K17: =IFERROR('Q2_Ratio'!P5+0,0) | L17: =IFERROR('Q2_Ratio'!P6+0,0) | M17: =IFERROR('Q2_Ratio'!P7+0,0) | N17: =IFERROR('Q2_Ratio'!P8+0,0) | O17: =IFERROR('Q2_Ratio'!P9+0,0) | P17: =IFERROR('Q2_Ratio'!P10+0,0) | Q17: =IFERROR('Q2_Ratio'!P11+0,0) | S17: 13 | T17: =IFERROR(INDEX('Q1_Verdeling'!$C$5:$Z$11,Grafieken!$AB$8,13+1)+0,0) | U17: =MAX($V17-$T17,0) | V17: =IFERROR(INDEX('Q2_Ratio'!$C$5:$Z$11,Grafieken!$AB$8,13+1)+0,0) | W17: =IFERROR($T17/$V17,0)
